Workbook
Name ESP: #REF!
Name FF: #REF!
Name TEMP: #REF!

Sheet COTAÇÃO DCP
X6: orçamento
X7: pint int
X8: termica
X9: industrial
X10: pisos
X11: residencial
O58: Serviços e Atividades Realizadas de Acordo as Normas ABNT e IT 08 e IT 10
B63: Data: | E63: ='PLAN ESP'!F3 -> 43882
B64: Cliente: | E64: ='PLAN ESP'!F4 -> MACERLO FERNANDO
B65: A/C: | E65: ='PLAN ESP'!F5 -> MARCELO | L65: Telefone: | O65: ='PLAN ESP'!P5 -> 949679592
B66: Obra: | E66: ='PLAN ESP'!F6 -> CASA 1
B67: Ref.: | E67: ='PLAN ESP'!F7 -> Proteção Passiva – Pintura Intumescente em Estrutura Metálica
B69: Prezado Srs.
B71: Atendendo à solicitação, temos à satisfação de submeter a vossa apreciação nossa proposta comercial técnica para fornecimento de pintura de PROTEÇÃO PASSIVA CONTRA O FOGO - PINTURA INTUMESCENTE DE ALTA QUALIDADE, a fim de atender as legislações em vigor do Corpo de Bombeiros e o Decreto Estadual N. 63.911 de 10.12.2018. Permanecendo à disposição para eventuais esclarecimentos. Agradecemos pela oportunidade de podermos participar deste processo, e reafirmarmos nosso interesse em fornecer sistemas de isolamento corta fogo de alta qualidade à sua empresa.
B81: Obrigado.
B83: Atenciosamente,
B84: André Nogueira Responsável Técnico CRQ IV Região - 04165118 (11) 98694.8801 andre@dcppinturastecnicas.com.br www.dcppinturastecnicas.com.br
B93: PROPOSTA TÉCNICO COMERCIAL
B94: PINTURA INTUMESCENTE – PROTEÇÃO PASSIVA PROTEÇÃO CONTRA INCÊNDIOS
B95: O sistema de proteção passiva por PINTURAS INTUMESCENTES é processo de proteção de estruturas metálicas e ou outros materiais previstas por normas nacionais e internacionais para que em um determinado local em situação de fogo possa haver tempo de evacuação do local, assim também como tempo de chegada e saída do local pelo Corpo de Bombeiros com proteção a vida e proteção ao patrimônio.
B97: NORMAS APLICÁVEIS
B98: Os materiais e serviços especificados, relativos ao serviço acima, obedecem às seguintes normas e Instruções pertinentes.
B100: NBR 14432 | E100: Exigências De Resistência Ao Fogo De Elementos Construtivos De Edificações Procedimento
B101: IT-08 CBSP | E101: Resistência Ao Fogo Dos Elementos De Construção
B102: ASTM E-119 | E102: Fire Tests of Building Construction and Materials
B103: ICC AC23 | E103: Acceptance Criteria or Spray-Applied and Intumescent Mastic Coating Fire-Protection Materials
B104: 63911 | E104: Decreto Estadual de 10.12.2018
B106: 1. | C106: SISTEMA DE PROTEÇÃO UTILIZADO
B108: Conforme determinado, será aplicada para proteção da estrutura metálica a TINTA INTUMESCENTE SHERWIN WILLIANS FIRETEX FX 5062 - Balde 20 Litros. Tinta certificada pelo Laboratório WarringtonFire Testing and Certification Limited sob Certificate Of Approval N. CF 5267, valido até dia 05 de agosto de 2024.
B110: 2. | C110: ENQUADRAMENTO DA EDIFICAÇÃO
C111: Conforme Tabela A da Norma NBR 14432 e IT 08
B113: 2.1 - Grupo: | L113: ='PLAN ESP'!E15 -> G
B114: 2.2 - Ocupação de Uso: | L114: ='PLAN ESP'!E16 -> COMERCIAL
B115: 2.3 - Enquadramento da Edificação: | L115: ='PLAN ESP'!E17 -> > 30 m/h
B117: 3. | C117: TRRF – TEMPO REQUERIDO DE RESISTÊNCIA AO FOGO
B119: Conforme informado pelo cliente, a espessura de proteção está dimensionada para atendimento a um TRRF de:
O123: ='PLAN ESP'!E14 -> 60 MINUTOS
B127: 4. | C127: ESCOPO DAS ATIVIDADES DE APLICAÇÃO PINTURA INTUMESCENTE
C128: Sistema de Pintura a ser realizado:
C130: Esmerilhamento e ou lixamento e ou limpeza da superfície;
...

Sheet PLAN ESP
C3: Data: | F3: =TODAY() -> 43882
C4: Cliente: | F4: MACERLO FERNANDO
C5: A/C: | F5: MARCELO | M5: Telefone: | P5: 949679592
C6: Obra: | F6: CASA 1
C7: Ref.: | F7: Proteção Passiva – Pintura Intumescente em Estrutura Metálica
C10: DCP PINTURAS TÉCNICAS
C11: CLIENTE: | E11: =F4 -> MACERLO FERNANDO | V11: SÓLIDOS %
C12: OBRA: | E12: =F6 -> CASA 1 | O12: PRODUTO | R12: SHERWIN WILLIANS FIRETEX FX 5062 | V12: 0.7
C13: CALCULADO POR: | E13: ANDRE NOGUEIRA | O13: ÁREA | R13: =SUM(T20:T35) -> 699.708 | U13: m²
C14: TEMPO RESIST. FOGO: | E14: 60 MINUTOS | O14: QTDE | R14: =SUM(V20:V35) -> 302.50616 | U14: ltr
C15: GRUPO | E15: G | R15: =R14/20 -> 15.125308 | T15: bd | U15: 0.1 | V15: PERDA
C16: OCUPAÇÃO DE USO | E16: COMERCIAL | U16: =(R15*U15)+R15 -> 16.637839
C17: CLASSE | E17: > 30 m/h
C18: REFERÊNCIA | D18: PERFIL | E18: EIXOS | G18: FACES | H18: d | I18: bf | J18: tw | K18: tf | L18: Hp | M18: PESO | N18: SEÇÃO | O18: Hp/A | P18: W/D | Q18: QTDE | R18: PESO | S18: COMPR. | T18: ÁREA | U18: ESP | V18: QTDE
E19: ALFA | F19: NÚMERO | H19: (mm) | I19: (mm) | J19: (mm) | K19: (mm) | L19: (m) | M19: (kg/m) | N19: (m²) | O19: (m-1) | R19: (kg) | S19: (mm) | T19: (m²) | U19: (mm) | V19: (ltr)
C20: COLUNA | D20: W 610 x 174,0 | G20: 4 | H20: =VLOOKUP(D20,PERFIS!$A$2:$F$559,2,FALSE) -> 616 | I20: =VLOOKUP(D20,PERFIS!$A$2:$F$559,3,FALSE) -> 325 | J20: =VLOOKUP(D20,PERFIS!$A$2:$F$559,4,FALSE) -> 14 | K20: =VLOOKUP(D20,PERFIS!$A$2:$F$559,5,FALSE) -> 21.6 | L20: =((2*H20)+(G20*I20))/1000 -> 2.532 | M20: =VLOOKUP(D20,PERFIS!$A$2:$F$559,6,FALSE) -> 174 | O20: =L20/(M20/7850) -> 114.23103 | P20: =39.37008/(M20*2.2) -> 0.10284765 | Q20: 9 | S20: 7 | T20: =S20*Q20*L20 -> 159.516 | U20: 0.251 | V20: =1.4*U20*T20 -> 56.053922
C21: VIGA | D21: W 200 x 19,3 | G21: 3 | H21: =VLOOKUP(D21,PERFIS!$A$2:$F$559,2,FALSE) -> 203 | I21: =VLOOKUP(D21,PERFIS!$A$2:$F$559,3,FALSE) -> 102 | J21: =VLOOKUP(D21,PERFIS!$A$2:$F$559,4,FALSE) -> 5.8 | K21: =VLOOKUP(D21,PERFIS!$A$2:$F$559,5,FALSE) -> 6.5 | L21: =((2*H21)+(G21*I21))/1000 -> 0.712 | M21: =VLOOKUP(D21,PERFIS!$A$2:$F$559,6,FALSE) -> 19.3 | O21: =L21/(M21/7850) -> 289.59585 | P21: =39.37008/(M21*2.2) -> 0.92722751 | Q21: 14 | S21: 12 | T21: =S21*Q21*L21 -> 119.616 | U21: 0.445 | V21: =1.4*U21*T21 -> 74.520768
C22: VIGA | D22: W 410 x 60,0 | G22: 3 | H22: =VLOOKUP(D22,PERFIS!$A$2:$F$559,2,FALSE) -> 407 | I22: =VLOOKUP(D22,PERFIS!$A$2:$F$559,3,FALSE) -> 178 | J22: =VLOOKUP(D22,PERFIS!$A$2:$F$559,4,FALSE) -> 7.7 | K22: =VLOOKUP(D22,PERFIS!$A$2:$F$559,5,FALSE) -> 12.8 | L22: =((2*H22)+(G22*I22))/1000 -> 1.348 | M22: =VLOOKUP(D22,PERFIS!$A$2:$F$559,6,FALSE) -> 60 | O22: =L22/(M22/7850) -> 176.36333 | P22: =39.37008/(M22*2.2) -> 0.29825818 | Q22: 26 | S22: 12 | T22: =S22*Q22*L22 -> 420.576 | U22: 0.292 | V22: =1.4*U22*T22 -> 171.93147
D23: PERFIL
D24: PERFIL
D25: PERFIL
D26: PERFIL
D27: PERFIL
D28: PERFIL
D29: PERFIL
D30: PERFIL
D31: PERFIL
D32: PERFIL
D33: PERFIL
D34: PERFIL
... D37: PRODUTOS
D39: QUANT. | F39: UNIDADE | H39: DESCRIÇÃO DE PRODUTOS | P39: R$ UNITÁRIO | S39: R$ SUBTOTAL
D40: 5 | F40: 3,6 l | H40: Fundo Promotor de Aderência Epóxi | P40: 160 | S40: =D40*P40 -> 800
D41: 1 | F41: 18 l | H41: Solvente Epóxi | P41: 200 | S41: =D41*P41 -> 200
D42: =U16 -> 16.637839 | F42: 20 l | H42: Tinta Intumescente SW FIRETEX TX 5062 | P42: 1186 | S42: =D42*P42 -> 19732.477
D43: 3 | F43: 18 l | H43: Top Coat - Tinta PU SW | P43: 430 | S43: =D43*P43 -> 1290
D44: 1 | F44: 18 l | H44: Solvente PU | P44: 200 | S44: =D44*P44 -> 200
P45: 0 | S45: =D45*P45 -> 0
P46: 0 | S46: =D46*P46 -> 0
H47: CUSTO TOTAL DE PRODUTOS PARA ATIVIDADES | S47: =SUM(S40:U46) -> 22222.477
...

Sheet ORÇAMENTARIA
C3: Data | D3: =TODAY() -> 43882 | F3: O.S - Nº
C4: PLANILHA ORÇAMENTÁRIA
C5: DADOS CADASTRAIS
C6: ÁREA m² | D6: ='PLAN ESP'!D52 -> 699.708
C7: CUSTO GERAL | G7: =G24+G37+G45+G16 -> 16881.923
C8: B.D.I | F8: =G8/G9 -> 0.41153423 | G8: =G9-G7-I7 -> 11806.105
C9: ORÇAMENTO DA OBRA | G9: ='PLAN ESP'!S56 -> 28688.028
C11: MATERIAIS | D11: UNID | E11: QTDS. | F11: VLR. UNIT. | G11: VLR. TOTAL
F12: 0 | G12: =L3 -> 0
F13: 0 | G13: =F13*E13 -> 0
F14: 0 | G14: =F14*E14 -> 0
F15: 0 | G15: =F15*E15 -> 0
C16: TOTAL | G16: =SUM(G12:G15) -> 0
C18: EQUIPAMENTOS | D18: TIPOS | E18: QTDS. | F18: VLR. UNIT. | G18: VLR. TOTAL
C19: Plataformas Tesoura 10 mt | D19: http://www.maxtra.com.br/ | E19: 1 | F19: 0 | G19: =F19*E19 -> 0
C20: Trinchas/Rolos/Acessorios | E20: 1 | F20: 0 | G20: =F20*E20 -> 0
C21: Thinner | E21: 1 | F21: 5000 | G21: =F21*E21 -> 5000
C22: Outros | E22: 1 | F22: 0 | G22: =F22*E22 -> 0
C23: ART | E23: 1 | F23: 450 | G23: =F23*E23 -> 450
C24: TOTAL | G24: =SUM(G19:G23) -> 5450
C26: MÃO DE OBRA | D26: QTDE | E26: PRAZO (DIAS) | F26: VLR.UNIT | G26: VLR. TOTAL
C27: APLICADOR/PINTOR | D27: 2 | E27: 15 | F27: 150 | G27: =F27*E27*D27 -> 4500
C28: AJUDANTE | D28: 2 | E28: 15 | F28: 100 | G28: =F28*E28*D28 -> 3000
C29: COMBUSTÍVEL | G29: =F29*E29*D29 -> 0
C30: PEDÁGIO | G30: =F30*E30*D30 -> 0
C31: ALIMENTAÇÃO | D31: 2 | E31: 15 | F31: 20 | G31: =F31*E31*D31 -> 600
C32: TRANSPORTE | D32: 2 | E32: 15 | F32: 25 | G32: =F32*E32*D32 -> 750
C33: HOSPEDAGEM | G33: =F33*E33*D33 -> 0
G34: =F34*E34*D34 -> 0
G35: =F35*E35*D35 -> 0
G36: =F36*E36*D36 -> 0
C37: TOTAL | G37: =SUM(G27:G36) -> 8850
C39: IMPOSTO | D39: SOBRE | E39: VLR. N.F | F39: ( % ) N.F | G39: VLR. IMPOSTOS
C40: MATERIAIS | D40: N.F | E40: 0 | F40: 0 | G40: =E40*F40 -> 0
C41: GERAL | D41: N.F | E41: =G9 -> 28688.028 | F41: 0.09 | G41: =E41*F41 -> 2581.9225
C42: INSS | D42: M.O | E42: 0 | F42: 0 | G42: =E42*F42 -> 0
C43: ISS | D43: LOCAL | E43: 0 | F43: 0 | G43: =E43*F43 -> 0
C44: IR | D44: N.F | E44: 0 | F44: 0 | G44: =E44*F44 -> 0
C45: TOTAL | G45: =SUM(G40:G44) -> 2581.9225

Sheet CARTA DE COBERTURA
B2: FIRETEX FX 5062 e FX 5090 | H2: FIRETEX FX 5062 e FX 5090 | N2: INTERNACIONAL INTERCHAR 1260 | S2: INTERNACIONAL INTERCHAR 1260 | X2: AUDAX PMA 600 / PMA 1200 | AC2: AUDAX PMA 600 / PMA 1200 | AH2: JOTUN STEEALMASTER 600 WF - CF 5631 | AK2: JOTUN CF 5243 | AM2: JOTUN STEEALMASTER 600 WF - CF 5631 | AP2: CF 5243
B3: VIGAS - Temp. Critica 620 oC - FX5062 | E3: FX5090 | H3: COLUNAS - Temp. Critica 550 oC - FX5062 | K3: FX5090 | N3: VIGAS - Temp. Critica 620 oC | S3: COLUNAS - Temp. Critica 550 oC | X3: VIGAS - Temp. Critica 620 oC - PMA 600 | AA3: PMA 1200 | AC3: COLUNAS - Temp. Critica 550 oC - PMA 600 | AF3: PMA 1200 | AH3: VIGAS - Temp. Critica 620 oC - WF 600 | AK3: WF 1200 | AM3: COLUNAS - Temp. Critica 550 oC -WF 600 | AP3: WF 1200
A4: HP/A | B4: 30 Min | C4: 60 Min | D4: 90 Min | E4: 90 Min | F4: 120 Min | G4: HP/A | H4: 30 Min | I4: 60 Min | J4: 90 Min | K4: 90 Min | L4: 120 Min | M4: HP/A | N4: 30 Min | O4: 60 Min | P4: 90 Min | Q4: 120 Min | R4: HP/A | S4: 30 Min | T4: 60 Min | U4: 90 Min | V4: 120 Min | W4: HP/A | X4: 30 Min | Y4: 60 Min | Z4: 90 Min | AA4: 120 Min | AB4: HP/A | AC4: 30 Min | AD4: 60 Min | AE4: 90 Min | AF4: 120 Min | AG4: HP/A | AH4: 30 Min | AI4: 60 Min | AJ4: 90 Min | AK4: 120 Min | AL4: HP/A | AM4: 30 Min | AN4: 60 Min | AO4: 90 Min | AP4: 120 Min
A5: 70 | B5: 0.181 | C5: 0.181 | D5: 0.286 | F5: 0.196 | G5: 70 | H5: 0.174 | I5: 0.176 | J5: 0.53 | L5: 1.857 | M5: 70 | N5: 0.135 | O5: 0.254 | P5: 0.448 | R5: 70 | W5: 70 | Y5: 0.191 | Z5: 0.46 | AA5: 0.951 | AB5: 70 | AE5: 0.463 | AF5: 1.511 | AG5: 70 | AH5: 0.154 | AI5: 0.154 | AJ5: 0.285 | AK5: 1.147 | AL5: 70 | AM5: 0.141 | AN5: 0.176 | AO5: 0.432 | AP5: 1.235
A6: 75 | B6: 0.181 | C6: 0.181 | D6: 0.303 | F6: 0.196 | G6: 75 | H6: 0.174 | I6: 0.184 | J6: 0.543 | L6: 1.988 | M6: 75 | N6: 0.135 | O6: 0.26 | P6: 0.458 | R6: 75 | W6: 75 | Y6: 0.204 | Z6: 0.493 | AA6: 1.031 | AB6: 75 | AE6: 0.496 | AF6: 1.593 | AG6: 75 | AH6: 0.154 | AI6: 0.154 | AJ6: 0.299 | AK6: 1.186 | AL6: 75 | AM6: 0.141 | AN6: 0.182 | AO6: 0.442 | AP6: 1.294
A7: 80 | B7: 0.181 | C7: 0.181 | D7: 0.32 | F7: 0.196 | G7: 80 | H7: 0.174 | I7: 0.193 | J7: 0.556 | L7: 2.119 | M7: 80 | N7: 0.135 | O7: 0.266 | P7: 0.469 | R7: 80 | W7: 80 | Y7: 0.216 | Z7: 0.526 | AA7: 1.111 | AB7: 80 | AD7: 0.214 | AE7: 0.529 | AF7: 1.675 | AG7: 80 | AH7: 0.154 | AI7: 0.154 | AJ7: 0.314 | AK7: 1.225 | AL7: 80 | AM7: 0.141 | AN7: 0.189 | AO7: 0.452 | AP7: 1.353
A8: 85 | B8: 0.181 | C8: 0.181 | D8: 0.337 | F8: 0.196 | G8: 85 | H8: 0.174 | I8: 0.201 | J8: 0.568 | L8: 2.25 | M8: 85 | N8: 0.135 | O8: 0.272 | P8: 0.479 | R8: 85 | W8: 85 | Y8: 0.229 | Z8: 0.558 | AA8: 1.19 | AB8: 85 | AD8: 0.241 | AE8: 0.562 | AF8: 1.757 | AG8: 85 | AH8: 0.154 | AI8: 0.154 | AJ8: 0.328 | AK8: 1.265 | AL8: 85 | AM8: 0.141 | AN8: 0.196 | AO8: 0.462 | AP8: 1.412
A9: 90 | B9: 0.181 | C9: 0.184 | D9: 0.354 | F9: 0.196 | G9: 90 | H9: 0.174 | I9: 0.209 | J9: 0.581 | L9: 2.381 | M9: 90 | N9: 0.135 | O9: 0.278 | P9: 0.489 | R9: 90 | S9: 0.143 | T9: 0.198 | U9: 0.504 | W9: 90 | Y9: 0.242 | Z9: 0.591 | AA9: 1.27 | AB9: 90 | AD9: 0.267 | AE9: 0.595 | AF9: 1.839 | AG9: 90 | AH9: 0.154 | AI9: 0.154 | AJ9: 0.342 | AK9: 1.304 | AL9: 90 | AM9: 0.141 | AN9: 0.203 | AO9: 0.473 | AP9: 1.471
A10: 95 | B10: 0.181 | C10: 0.189 | D10: 0.371 | F10: 0.196 | G10: 95 | H10: 0.174 | I10: 0.217 | J10: 0.594 | L10: 2.505 | M10: 95 | N10: 0.135 | O10: 0.284 | P10: 0.5 | R10: 95 | S10: 0.143 | T10: 0.207 | U10: 0.52 | W10: 95 | Y10: 0.254 | Z10: 0.624 | AA10: 1.35 | AB10: 95 | AD10: 0.294 | AE10: 0.628 | AF10: 1.922 | AG10: 95 | AH10: 0.154 | AI10: 0.154 | AJ10: 0.356 | AK10: 1.343 | AL10: 95 | AM10: 0.141 | AN10: 0.21 | AO10: 0.483 | AP10: 1.53
A11: 100 | B11: 0.181 | C11: 0.194 | D11: 0.388 | F11: 0.196 | G11: 100 | H11: 0.174 | I11: 0.226 | J11: 0.606 | L11: 2.572 | M11: 100 | N11: 0.135 | O11: 0.289 | P11: 0.51 | R11: 100 | S11: 0.143 | T11: 0.215 | U11: 0.537 | W11: 100 | Y11: 0.267 | Z11: 0.657 | AA11: 1.429 | AB11: 100 | AC11: 0.207 | AD11: 0.321 | AE11: 0.661 | AF11: 2.004 | AG11: 100 | AH11: 0.154 | AI11: 0.16 | AJ11: 0.371 | AK11: 1.382 | AL11: 100 | AM11: 0.141 | AN11: 0.217 | AO11: 0.493 | AP11: 1.589
A12: 105 | B12: 0.181 | C12: 0.199 | D12: 0.405 | F12: 0.196 | G12: 105 | H12: 0.174 | I12: 0.234 | J12: 0.619 | L12: 2.64 | M12: 105 | N12: 0.135 | O12: 0.295 | P12: 0.521 | R12: 105 | S12: 0.143 | T12: 0.224 | U12: 0.554 | W12: 105 | Y12: 0.279 | Z12: 0.69 | AA12: 1.509 | AB12: 105 | AC12: 0.208 | AD12: 0.347 | AE12: 0.694 | AF12: 2.086 | AG12: 105 | AH12: 0.154 | AI12: 0.166 | AJ12: 0.385 | AK12: 1.422 | AL12: 105 | AM12: 0.141 | AN12: 0.224 | AO12: 0.504 | AP12: 1.648
A13: 110 | B13: 0.181 | C13: 0.204 | D13: 0.426 | F13: 0.196 | G13: 110 | H13: 0.174 | I13: 0.242 | J13: 0.632 | L13: 2.707 | M13: 110 | N13: 0.135 | O13: 0.301 | P13: 0.531 | R13: 110 | S13: 0.143 | T13: 0.233 | U13: 0.578 | W13: 110 | Y13: 0.292 | Z13: 0.723 | AA13: 1.589 | AB13: 110 | AC13: 0.212 | AD13: 0.374 | AE13: 0.727 | AF13: 2.168 | AG13: 110 | AH13: 0.154 | AI13: 0.171 | AJ13: 0.399 | AK13: 1.461 | AL13: 110 | AM13: 0.141 | AN13: 0.231 | AO13: 0.514 | AP13: 1.707
A14: 115 | B14: 0.181 | C14: 0.209 | D14: 0.446 | F14: 0.196 | G14: 115 | H14: 0.174 | I14: 0.251 | J14: 0.645 | L14: 2.774 | M14: 115 | N14: 0.135 | O14: 0.307 | P14: 0.542 | R14: 115 | S14: 0.143 | T14: 0.242 | U14: 0.602 | W14: 115 | Y14: 0.305 | Z14: 0.755 | AA14: 1.668 | AB14: 115 | AC14: 0.215 | AD14: 0.401 | AE14: 0.76 | AF14: 2.25 | AG14: 115 | AH14: 0.154 | AI14: 0.177 | AJ14: 0.413 | AK14: 1.5 | AL14: 115 | AM14: 0.141 | AN14: 0.238 | AO14: 0.524 | AP14: 1.766
A15: 120 | B15: 0.181 | C15: 0.214 | D15: 0.467 | F15: 0.196 | G15: 120 | H15: 0.174 | I15: 0.259 | J15: 0.657 | L15: 2.842 | M15: 120 | N15: 0.135 | O15: 0.313 | P15: 0.555 | R15: 120 | S15: 0.143 | T15: 0.25 | U15: 0.626 | W15: 120 | Y15: 0.317 | Z15: 0.788 | AA15: 1.748 | AB15: 120 | AC15: 0.219 | AD15: 0.428 | AE15: 0.793 | AF15: 2.332 | AG15: 120 | AH15: 0.154 | AI15: 0.183 | AJ15: 0.428 | AK15: 1.539 | AL15: 120 | AM15: 0.141 | AN15: 0.244 | AO15: 0.534 | AP15: 1.825
A16: 125 | B16: 0.181 | C16: 0.219 | D16: 0.487 | F16: 0.196 | G16: 125 | H16: 0.174 | I16: 0.267 | J16: 0.67 | L16: 2.909 | M16: 125 | N16: 0.135 | O16: 0.319 | P16: 0.579 | R16: 125 | S16: 0.143 | T16: 0.259 | U16: 0.65 | W16: 125 | Y16: 0.33 | Z16: 0.821 | AA16: 1.82 | AB16: 125 | AC16: 0.223 | AD16: 0.454 | AE16: 0.826 | AF16: 2.414 | AG16: 125 | AH16: 0.154 | AI16: 0.189 | AJ16: 0.445 | AK16: 1.579 | AL16: 125 | AM16: 0.141 | AN16: 0.251 | AO16: 0.545 | AP16: 1.884
A17: 130 | B17: 0.181 | C17: 0.223 | D17: 0.508 | F17: 0.196 | G17: 130 | H17: 0.174 | I17: 0.275 | J17: 0.683 | L17: 2.976 | M17: 130 | N17: 0.135 | O17: 0.325 | P17: 0.603 | R17: 130 | S17: 0.143 | T17: 0.268 | U17: 0.674 | W17: 130 | Y17: 0.342 | Z17: 0.854 | AA17: 1.874 | AB17: 130 | AC17: 0.226 | AD17: 0.481 | AE17: 0.859 | AF17: 2.496 | AG17: 130 | AH17: 0.154 | AI17: 0.194 | AJ17: 0.463 | AK17: 1.618 | AL17: 130 | AM17: 0.141 | AN17: 0.258 | AO17: 0.555 | AP17: 1.943
A18: 135 | B18: 0.181 | C18: 0.228 | D18: 0.528 | F18: 0.196 | G18: 135 | H18: 0.174 | I18: 0.284 | J18: 0.696 | L18: 3.043 | M18: 135 | N18: 0.135 | O18: 0.33 | P18: 0.628 | R18: 135 | S18: 0.143 | T18: 0.276 | U18: 0.698 | W18: 135 | Y18: 0.355 | Z18: 0.887 | AA18: 1.928 | AB18: 135 | AC18: 0.23 | AD18: 0.508 | AE18: 0.892 | AF18: 2.578 | AG18: 135 | AH18: 0.154 | AI18: 0.2 | AJ18: 0.481 | AK18: 1.657 | AL18: 135 | AM18: 0.141 | AN18: 0.265 | AO18: 0.565 | AP18: 2.002
A19: 140 | B19: 0.181 | C19: 0.233 | D19: 0.549 | F19: 0.196 | G19: 140 | H19: 0.174 | I19: 0.292 | J19: 0.708 | L19: 3.111 | M19: 140 | N19: 0.135 | O19: 0.336 | P19: 0.652 | R19: 140 | S19: 0.143 | T19: 0.285 | U19: 0.722 | W19: 140 | Y19: 0.368 | Z19: 0.92 | AA19: 1.982 | AB19: 140 | AC19: 0.234 | AD19: 0.534 | AE19: 0.925 | AF19: 2.66 | AG19: 140 | AH19: 0.154 | AI19: 0.206 | AJ19: 0.499 | AK19: 1.696 | AL19: 140 | AM19: 0.141 | AN19: 0.272 | AO19: 0.575 | AP19: 2.06
A20: 145 | B20: 0.181 | C20: 0.238 | D20: 0.569 | F20: 0.196 | G20: 145 | H20: 0.174 | I20: 0.3 | J20: 0.721 | L20: 3.178 | M20: 145 | N20: 0.135 | O20: 0.342 | P20: 0.676 | R20: 145 | S20: 0.143 | T20: 0.294 | U20: 0.746 | W20: 145 | Y20: 0.38 | Z20: 0.953 | AA20: 2.035 | AB20: 145 | AC20: 0.237 | AD20: 0.561 | AE20: 0.958 | AF20: 2.743 | AG20: 145 | AH20: 0.154 | AI20: 0.212 | AJ20: 0.517 | AK20: 1.736 | AL20: 145 | AM20: 0.141 | AN20: 0.279 | AO20: 0.586 | AP20: 2.119
A21: 150 | B21: 0.181 | C21: 0.243 | D21: 0.592 | F21: 0.196 | G21: 150 | H21: 0.174 | I21: 0.309 | J21: 0.734 | L21: 3.245 | M21: 150 | N21: 0.135 | O21: 0.348 | P21: 0.7 | R21: 150 | S21: 0.143 | T21: 0.303 | U21: 0.77 | W21: 150 | Y21: 0.393 | Z21: 0.985 | AA21: 2.089 | AB21: 150 | AC21: 0.241 | AD21: 0.588 | AE21: 0.991 | AF21: 2.825 | AG21: 150 | AH21: 0.154 | AI21: 0.217 | AJ21: 0.535 | AK21: 1.775 | AL21: 150 | AM21: 0.141 | AN21: 0.286 | AO21: 0.596 | AP21: 2.178
A22: 155 | B22: 0.181 | C22: 0.248 | D22: 0.618 | F22: 0.196 | G22: 155 | H22: 0.174 | I22: 0.317 | J22: 0.747 | L22: 3.313 | M22: 155 | N22: 0.135 | O22: 0.354 | P22: 0.725 | R22: 155 | S22: 0.143 | T22: 0.311 | U22: 0.794 | W22: 155 | Y22: 0.405 | Z22: 1.018 | AA22: 2.143 | AB22: 155 | AC22: 0.245 | AD22: 0.615 | AE22: 1.024 | AF22: 2.907 | AG22: 155 | AH22: 0.154 | AI22: 0.223 | AJ22: 0.553 | AK22: 1.814 | AL22: 155 | AM22: 0.141 | AN22: 0.293 | AO22: 0.606 | AP22: 2.237
... A25: 170 | B25: 0.181 | C25: 0.263 | D25: 0.673 | F25: 0.196 | G25: 170 | H25: 0.174 | I25: 0.342 | J25: 0.785 | L25: 3.511 | M25: 170 | N25: 0.135 | O25: 0.371 | P25: 0.798 | R25: 170 | S25: 0.143 | T25: 0.337 | U25: 0.866 | W25: 170 | Y25: 0.443 | Z25: 1.117 | AA25: 2.304 | AB25: 170 | AC25: 0.256 | AD25: 0.664 | AE25: 1.124 | AF25: 3.153 | AG25: 170 | AH25: 0.154 | AI25: 0.24 | AJ25: 0.607 | AK25: 1.932 | AL25: 170 | AM25: 0.141 | AN25: 0.313 | AO25: 0.639 | AP25: 2.414
A26: 175 | B26: 0.181 | C26: 0.267 | D26: 0.695 | F26: 0.196 | G26: 175 | H26: 0.174 | I26: 0.35 | J26: 0.798 | L26: 3.569 | M26: 175 | N26: 0.135 | O26: 0.377 | P26: 0.822 | R26: 175 | S26: 0.143 | T26: 0.346 | U26: 0.89 | W26: 175 | Y26: 0.456 | AA26: 2.358 | AB26: 175 | AC26: 0.259 | AD26: 0.679 | AE26: 1.157 | AF26: 3.235 | AG26: 175 | AH26: 0.154 | AI26: 0.246 | AJ26: 0.625 | AK26: 1.971 | AL26: 175 | AM26: 0.141 | AN26: 0.32 | AO26: 0.65 | AP26: 2.473
A27: 180 | B27: 0.181 | C27: 0.272 | D27: 0.716 | F27: 0.196 | G27: 180 | H27: 0.174 | I27: 0.358 | J27: 0.81 | L27: 3.626 | M27: 180 | N27: 0.135 | O27: 0.383 | P27: 0.846 | R27: 180 | S27: 0.143 | T27: 0.355 | U27: 0.914 | W27: 180 | Y27: 0.469 | AA27: 2.411 | AB27: 180 | AC27: 0.263 | AD27: 0.695 | AE27: 1.19 | AF27: 3.317 | AG27: 180 | AH27: 0.154 | AI27: 0.252 | AK27: 2.01 | AL27: 180 | AM27: 0.141 | AN27: 0.327 | AO27: 0.661 | AP27: 2.542
A28: 185 | B28: 0.181 | C28: 0.277 | D28: 0.737 | F28: 0.196 | G28: 185 | H28: 0.174 | I28: 0.367 | J28: 0.823 | L28: 3.684 | M28: 185 | N28: 0.135 | O28: 0.389 | P28: 0.871 | R28: 185 | S28: 0.143 | T28: 0.364 | U28: 0.938 | W28: 185 | Y28: 0.481 | AA28: 2.465 | AB28: 185 | AC28: 0.267 | AD28: 0.71 | AE28: 1.223 | AF28: 3.399 | AG28: 185 | AH28: 0.154 | AI28: 0.258 | AK28: 2.05 | AL28: 185 | AM28: 0.141 | AN28: 0.334 | AO28: 0.672 | AP28: 2.633
A29: 190 | B29: 0.181 | C29: 0.282 | D29: 0.758 | F29: 0.196 | G29: 190 | H29: 0.174 | I29: 0.375 | J29: 0.736 | L29: 3.741 | M29: 190 | N29: 0.135 | O29: 0.395 | P29: 0.895 | R29: 190 | S29: 0.143 | T29: 0.372 | U29: 0.962 | W29: 190 | Y29: 0.494 | AA29: 2.519 | AB29: 190 | AC29: 0.27 | AD29: 0.726 | AE29: 1.256 | AF29: 3.478 | AG29: 190 | AH29: 0.154 | AI29: 0.263 | AK29: 2.089 | AL29: 190 | AM29: 0.141 | AN29: 0.341 | AO29: 0.683 | AP29: 2.724
A30: 195 | B30: 0.181 | C30: 0.287 | D30: 0.779 | F30: 0.196 | G30: 195 | H30: 0.174 | I30: 0.383 | J30: 0.849 | L30: 3.799 | M30: 195 | N30: 0.135 | O30: 0.401 | P30: 0.919 | R30: 195 | S30: 0.143 | T30: 0.381 | U30: 0.986 | W30: 195 | Y30: 0.506 | AA30: 2.573 | AB30: 195 | AC30: 0.274 | AD30: 0.741 | AF30: 3.52 | AG30: 195 | AH30: 0.154 | AI30: 0.269 | AK30: 2.128 | AL30: 195 | AM30: 0.141 | AN30: 0.348 | AO30: 0.694 | AP30: 2.815
A31: 200 | B31: 0.181 | C31: 0.292 | D31: 0.801 | F31: 0.196 | G31: 200 | H31: 0.174 | I31: 0.392 | J31: 0.861 | L31: 3.856 | M31: 200 | N31: 0.135 | O31: 0.406 | P31: 0.943 | R31: 200 | S31: 0.143 | T31: 0.39 | U31: 1.009 | W31: 200 | Y31: 0.519 | AA31: 2.626 | AB31: 200 | AC31: 0.278 | AD31: 0.757 | AF31: 3.562 | AG31: 200 | AH31: 0.154 | AI31: 0.275 | AK31: 2.167 | AL31: 200 | AM31: 0.141 | AN31: 0.354 | AO31: 0.705 | AP31: 2.906
A32: 205 | B32: 0.181 | C32: 0.297 | D32: 0.822 | F32: 0.196 | G32: 205 | H32: 0.174 | I32: 0.4 | J32: 0.874 | L32: 3.914 | M32: 205 | N32: 0.135 | O32: 0.412 | P32: 0.963 | R32: 205 | S32: 0.143 | T32: 0.398 | U32: 1.033 | W32: 205 | Y32: 0.532 | AA32: 2.68 | AB32: 205 | AC32: 0.281 | AD32: 0.773 | AF32: 3.603 | AG32: 205 | AH32: 0.154 | AI32: 0.281 | AK32: 2.207 | AL32: 205 | AM32: 0.141 | AN32: 0.361 | AP32: 2.997
A33: 210 | B33: 0.181 | C33: 0.302 | D33: 0.843 | F33: 0.196 | G33: 210 | H33: 0.174 | I33: 0.408 | L33: 3.971 | M33: 210 | N33: 0.135 | O33: 0.418 | P33: 0.992 | R33: 210 | S33: 0.143 | T33: 0.407 | U33: 1.057 | W33: 210 | X33: 0.18 | Y33: 0.544 | AA33: 2.734 | AB33: 210 | AC33: 0.285 | AD33: 0.788 | AF33: 3.645 | AG33: 210 | AH33: 0.154 | AI33: 0.286 | AK33: 2.246 | AL33: 210 | AM33: 0.141 | AN33: 0.368 | AP33: 3.088
A34: 215 | B34: 0.181 | C34: 0.307 | D34: 0.864 | F34: 0.196 | G34: 215 | H34: 0.174 | I34: 0.416 | L34: 4.029 | M34: 215 | N34: 0.135 | O34: 0.424 | P34: 1.016 | R34: 215 | S34: 0.143 | T34: 0.416 | U34: 1.081 | W34: 215 | X34: 0.186 | Y34: 0.557 | AA34: 2.787 | AB34: 215 | AC34: 0.289 | AD34: 0.804 | AF34: 3.687 | AG34: 215 | AH34: 0.154 | AI34: 0.292 | AK34: 2.285 | AL34: 215 | AM34: 0.141 | AN34: 0.375 | AP34: 3.179
A35: 220 | B35: 0.181 | C35: 0.311 | D35: 0.886 | F35: 0.196 | G35: 220 | H35: 0.174 | I35: 0.425 | L35: 4.087 | M35: 220 | N35: 0.135 | O35: 0.43 | P35: 1.041 | R35: 220 | S35: 0.143 | T35: 0.425 | U35: 1.105 | W35: 220 | X35: 0.192 | Y35: 0.569 | AA35: 2.841 | AB35: 220 | AC35: 0.292 | AD35: 0.822 | AF35: 3.729 | AG35: 220 | AH35: 0.154 | AI35: 0.298 | AK35: 2.324 | AL35: 220 | AM35: 0.141 | AN35: 0.382 | AP35: 3.269
A36: 225 | B36: 0.181 | C36: 0.316 | F36: 0.196 | G36: 225 | H36: 0.174 | I36: 0.433 | L36: 4.144 | M36: 225 | N36: 0.135 | O36: 0.436 | P36: 1.065 | R36: 225 | S36: 0.143 | T36: 0.433 | U36: 1.129 | W36: 225 | X36: 0.198 | Y36: 0.582 | AA36: 2.895 | AB36: 225 | AC36: 0.296 | AD36: 0.842 | AF36: 3.771 | AG36: 225 | AH36: 0.154 | AI36: 0.304 | AK36: 2.364 | AL36: 225 | AM36: 0.141 | AN36: 0.389 | AP36: 3.36
A37: 230 | B37: 0.181 | C37: 0.321 | F37: 0.196 | G37: 230 | H37: 0.174 | I37: 0.441 | L37: 4.202 | M37: 230 | N37: 0.135 | O37: 0.442 | P37: 1.089 | R37: 230 | S37: 0.143 | T37: 0.442 | W37: 230 | X37: 0.203 | Y37: 0.595 | AA37: 2.949 | AB37: 230 | AC37: 0.3 | AD37: 0.861 | AF37: 3.813 | AG37: 230 | AH37: 0.154 | AI37: 0.309 | AK37: 2.403 | AL37: 230 | AM37: 0.141 | AN37: 0.396 | AP37: 3.451
A38: 235 | B38: 0.181 | C38: 0.326 | F38: 0.196 | G38: 235 | H38: 0.174 | I38: 0.45 | L38: 4.259 | M38: 235 | N38: 0.136 | O38: 0.447 | P38: 1.114 | R38: 235 | S38: 0.143 | T38: 0.451 | W38: 235 | X38: 0.209 | Y38: 0.607 | AA38: 3.002 | AB38: 235 | AC38: 0.303 | AD38: 0.881 | AF38: 3.855 | AG38: 235 | AH38: 0.154 | AI38: 0.315 | AK38: 2.442 | AL38: 235 | AM38: 0.141 | AN38: 0.403 | AP38: 3.542
A39: 240 | B39: 0.181 | C39: 0.331 | F39: 0.196 | G39: 240 | H39: 0.174 | I39: 0.458 | L39: 4.317 | M39: 240 | N39: 0.14 | O39: 0.453 | P39: 1.138 | R39: 240 | S39: 0.143 | T39: 0.459 | W39: 240 | X39: 0.215 | Y39: 0.62 | AA39: 3.056 | AB39: 240 | AC39: 0.307 | AD39: 0.901 | AF39: 3.897 | AG39: 240 | AH39: 0.154 | AI39: 0.321 | AK39: 2.481 | AL39: 240 | AM39: 0.141 | AN39: 0.409 | AP39: 3.633
A40: 245 | B40: 0.181 | C40: 0.336 | F40: 0.196 | G40: 245 | H40: 0.174 | I40: 0.466 | L40: 4.374 | M40: 245 | N40: 0.143 | O40: 0.459 | P40: 1.162 | R40: 245 | S40: 0.143 | T40: 0.468 | W40: 245 | X40: 0.221 | Y40: 0.66 | AA40: 3.111 | AB40: 245 | AC40: 0.311 | AD40: 0.921 | AF40: 3.939 | AG40: 245 | AH40: 0.154 | AI40: 0.326 | AK40: 2.523 | AL40: 245 | AM40: 0.141 | AN40: 0.416 | AP40: 3.724
A41: 250 | B41: 0.181 | C41: 0.341 | F41: 0.196 | G41: 250 | H41: 0.174 | I41: 0.474 | L41: 4.432 | M41: 250 | N41: 0.147 | O41: 0.465 | R41: 250 | S41: 0.143 | T41: 0.477 | W41: 250 | X41: 0.227 | Y41: 0.81 | AA41: 3.173 | AB41: 250 | AC41: 0.313 | AD41: 0.94 | AF41: 3.981 | AG41: 250 | AH41: 0.154 | AI41: 0.332 | AK41: 2.584 | AL41: 250 | AM41: 0.141 | AN41: 0.423 | AP41: 3.815
A42: 255 | B42: 0.181 | C42: 0.346 | F42: 0.197 | G42: 255 | H42: 0.174 | I42: 0.483 | L42: 4.489 | M42: 255 | N42: 0.15 | O42: 0.471 | R42: 255 | S42: 0.143 | T42: 0.486 | W42: 255 | X42: 0.232 | Y42: 0.82 | AA42: 3.325 | AB42: 255 | AC42: 0.316 | AD42: 0.96 | AF42: 4.023 | AG42: 255 | AH42: 0.154 | AI42: 0.338 | AK42: 2.646 | AL42: 255 | AM42: 0.141 | AN42: 0.434 | AP42: 3.906
A43: 260 | B43: 0.181 | C43: 0.351 | F43: 0.204 | G43: 260 | H43: 0.174 | I43: 0.491 | L43: 4.547 | M43: 260 | N43: 0.154 | O43: 0.477 | R43: 260 | S43: 0.143 | T43: 0.494 | W43: 260 | X43: 0.238 | Y43: 0.83 | AA43: 3.297 | AB43: 260 | AC43: 0.319 | AD43: 0.98 | AF43: 4.064 | AG43: 260 | AH43: 0.154 | AI43: 0.344 | AK43: 2.707 | AL43: 260 | AM43: 0.141 | AN43: 0.446 | AP43: 3.997
...

Sheet ANEXO A 14432
V20: Açs´WEPKF-

Sheet PERFIL GERDAU
A1: BITOLA | B1: MASSA LINEAR | C1: d | D1: bf | E1: ESPESSURA | G1: h | H1: d’ | I1: ÁREA | J1: PERIMETRO | K1: EIXO X-X | O1: EIXO Y-Y | S1: rt | T1: It | U1: ESBELTEZ | X1: Cw | Z1: ÁREA REDUZIDA | AA1: *CARGA ADM EST | AB1: *CARGA ADM EST | AC1: BITOLA
E2: tw | F2: tf | J2: u | K2: Ix | L2: Wx | M2: rx | N2: Zx | O2: Iy | P2: Wy | Q2: ry | R2: Zy | U2: ABA - λf | V2: ABA - λw | W2: Coef Red. Q | AA2: (Q.A's.fy)/1,66 | AB2: (Q.A's.fy)/2,00
A3: mm x kg/m | B3: kg/mL | C3: mm | D3: mm | E3: mm | F3: mm | G3: mm | H3: mm | I3: cm² | J3: cm | K3: cm⁴ | L3: cm³ | M3: cm | N3: cm³ | O3: cm⁴ | P3: cm³ | Q3: cm | R3: cm³ | S3: cm | T3: cm⁴ | U3: bf/2t | V3: d’/t | W3: ≤ 1,00 | X3: cm⁶ | Y3: m³/m | Z3: cm² | AA3: tf | AB3: tf | AC3: mm x kg/m
A4: W 150 x 13,0 | B4: 13 | C4: 148 | D4: 100 | E4: 4.3 | F4: 4.9 | G4: 138 | H4: 118 | I4: 16.6 | J4: 67 | K4: 635 | L4: 85.8 | M4: 6.18 | N4: 96.4 | O4: 82 | P4: 16.4 | Q4: 2.22 | R4: 25.5 | S4: 2.6 | T4: 1.72 | U4: 10.2 | V4: 27.49 | W4: 1 | X4: 4.181 | Y4: 0.67 | Z4: =AA4/2.1 -> 6.6666667 | AA4: 14 | AB4: 11.2 | AC4: W 150 x 13,0
A5: W 150 x 18,0 | B5: 18 | C5: 153 | D5: 102 | E5: 5.8 | F5: 7.1 | G5: 139 | H5: 119 | I5: 23.4 | J5: 69 | K5: 939 | L5: 122.8 | M5: 6.34 | N5: 139.4 | O5: 126 | P5: 24.7 | Q5: 2.32 | R5: 38.5 | S5: 2.69 | T5: 4.34 | U5: 7.18 | V5: 20.48 | W5: 1 | X5: 6.683 | Y5: 0.69 | Z5: =AA5/2.1 -> 13.333333 | AA5: 28 | AB5: 22.4 | AC5: W 150 x 18,0
A6: W 150 x 22,5 (H) | B6: 22.5 | C6: 152 | D6: 152 | E6: 5.8 | F6: 6.6 | G6: 139 | H6: 119 | I6: 29 | J6: 88 | K6: 1229 | L6: 161.7 | M6: 6.51 | N6: 179.6 | O6: 387 | P6: 50.9 | Q6: 3.65 | R6: 77.9 | S6: 4.1 | T6: 4.75 | U6: 11.52 | V6: 20.48 | W6: 1 | X6: 20.417 | Y6: 0.88 | Z6: =AA6/2.1 -> 15.714286 | AA6: 33 | AB6: 26.4 | AC6: W 150 x 22,5 (H)
A7: W 150 x 24,0 | B7: 24 | C7: 160 | D7: 102 | E7: 6.6 | F7: 10.3 | G7: 139 | H7: 115 | I7: 31.5 | J7: 69 | K7: 1384 | L7: 173 | M7: 6.63 | N7: 197.6 | O7: 183 | P7: 35.9 | Q7: 2.41 | R7: 55.8 | S7: 2.73 | T7: 11.08 | U7: 4.95 | V7: 17.48 | W7: 1 | X7: 10.206 | Y7: 0.69 | Z7: =AA7/2.1 -> 20.952381 | AA7: 44 | AB7: 35.2 | AC7: W 150 x 24,0
A8: W 150 x 29,8 (H) | B8: 29.8 | C8: 157 | D8: 153 | E8: 6.6 | F8: 9.3 | G8: 138 | H8: 118 | I8: 38.5 | J8: 90 | K8: 1739 | L8: 221.5 | M8: 6.72 | N8: 247.5 | O8: 556 | P8: 72.6 | Q8: 3.8 | R8: 110.8 | S8: 4.18 | T8: 10.95 | U8: 8.23 | V8: 17.94 | W8: 1 | X8: 30.277 | Y8: 0.9 | Z8: =AA8/2.1 -> 25.238095 | AA8: 53 | AB8: 42.4 | AC8: W 150 x 29,8 (H)
A9: W 150 x 37,1 (H) | B9: 37.1 | C9: 162 | D9: 154 | E9: 8.1 | F9: 11.6 | G9: 139 | H9: 119 | I9: 47.8 | J9: 91 | K9: 2244 | L9: 277 | M9: 6.85 | N9: 313.5 | O9: 707 | P9: 91.8 | Q9: 3.84 | R9: 140.4 | S9: 4.22 | T9: 20.58 | U9: 6.64 | V9: 14.67 | W9: 1 | X9: 39.93 | Y9: 0.91 | Z9: =AA9/2.1 -> 34.285714 | AA9: 72 | AB9: 57.6 | AC9: W 150 x 37,1 (H)
A10: W 200 x 15,0 | B10: 15 | C10: 200 | D10: 100 | E10: 4.3 | F10: 5.2 | G10: 190 | H10: 170 | I10: 19.4 | J10: 77 | K10: 1305 | L10: 130.5 | M10: 8.2 | N10: 147.9 | O10: 87 | P10: 17.4 | Q10: 2.12 | R10: 27.3 | S10: 2.55 | T10: 2.05 | U10: 9.62 | V10: 39.44 | W10: 0.95 | X10: 8.222 | Y10: 0.77 | Z10: =AA10/2.1 -> 7.6190476 | AA10: 16 | AB10: 12.8 | AC10: W 200 x 15,0
A11: W 200 x 19,3 | B11: 19.3 | C11: 203 | D11: 102 | E11: 5.8 | F11: 6.5 | G11: 190 | H11: 170 | I11: 25.1 | J11: 79 | K11: 1686 | L11: 166.1 | M11: 8.19 | N11: 190.6 | O11: 116 | P11: 22.7 | Q11: 2.14 | R11: 35.9 | S11: 2.59 | T11: 4.02 | U11: 7.85 | V11: 29.31 | W11: 1 | X11: 11.098 | Y11: 0.79 | Z11: =AA11/2.1 -> 13.333333 | AA11: 28 | AB11: 22.4 | AC11: W 200 x 19,3
A12: W 200 x 22,5 | B12: 22.5 | C12: 206 | D12: 102 | E12: 6.2 | F12: 8 | G12: 190 | H12: 170 | I12: 29 | J12: 79 | K12: 2029 | L12: 197 | M12: 8.37 | N12: 225.5 | O12: 142 | P12: 27.9 | Q12: 2.22 | R12: 43.9 | S12: 2.63 | T12: 6.18 | U12: 6.38 | V12: 27.42 | W12: 1 | X12: 13.868 | Y12: 0.79 | Z12: =AA12/2.1 -> 17.142857 | AA12: 36 | AB12: 28.8 | AC12: W 200 x 22,5
A13: W 200 x 26,6 | B13: 26.6 | C13: 207 | D13: 133 | E13: 5.8 | F13: 8.4 | G13: 190 | H13: 170 | I13: 34.2 | J13: 92 | K13: 2611 | L13: 252.3 | M13: 8.73 | N13: 282.3 | O13: 330 | P13: 49.6 | Q13: 3.1 | R13: 76.3 | S13: 3.54 | T13: 7.65 | U13: 7.92 | V13: 29.34 | W13: 1 | X13: 32.477 | Y13: 0.92 | Z13: =AA13/2.1 -> 20.47619 | AA13: 43 | AB13: 34.4 | AC13: W 200 x 26,6
A14: W 200 x 31,3 | B14: 31.3 | C14: 210 | D14: 134 | E14: 6.4 | F14: 10.2 | G14: 190 | H14: 170 | I14: 40.3 | J14: 93 | K14: 3168 | L14: 301.7 | M14: 8.86 | N14: 338.6 | O14: 410 | P14: 61.2 | Q14: 3.19 | R14: 94 | S14: 3.6 | T14: 12.59 | U14: 6.57 | V14: 26.5 | W14: 1 | X14: 40.822 | Y14: 0.93 | Z14: =AA14/2.1 -> 26.666667 | AA14: 56 | AB14: 44.8 | AC14: W 200 x 31,3
A15: W 200 x 35,9 (H) | B15: 35.9 | C15: 201 | D15: 165 | E15: 6.2 | F15: 10.2 | G15: 181 | H15: 161 | I15: 45.7 | J15: 103 | K15: 3437 | L15: 342 | M15: 8.67 | N15: 379.2 | O15: 764 | P15: 92.6 | Q15: 4.09 | R15: 141 | S15: 4.5 | T15: 14.51 | U15: 8.09 | V15: 25.9 | W15: 1 | X15: 69.502 | Y15: 1.03 | Z15: =AA15/2.1 -> 30.47619 | AA15: 64 | AB15: 51.2 | AC15: W 200 x 35,9 (H)
... A91: W 610 x 174,0 | B91: 174 | C91: 616 | D91: 325 | E91: 14 | F91: 21.6 | G91: 573 | H91: 541 | I91: 222.8 | J91: 248 | K91: 147754 | L91: 4797.2 | M91: 25.75 | N91: 5383.3 | O91: 12374 | P91: 761.5 | Q91: 7.45 | R91: 1171.1 | S91: 8.58 | T91: 286.88 | U91: 7.52 | V91: 38.63 | W91: 0.96 | X91: 10915665 | Y91: 2.48 | Z91: =AA91/2.1 -> 180 | AA91: 378 | AB91: 302.4 | AC91: W 610 x 174,0

Sheet CARTA DE COBERTURA AUX
A1: HP/A | B1: SHERWIN WILLIANS FIRETEX VIGA 30 | C1: SHERWIN WILLIANS FIRETEX VIGA 60 | D1: SHERWIN WILLIANS FIRETEX VIGA 90 | E1: SHERWIN WILLIANS FIRETEX VIGA 120 | F1: SHERWIN WILLIANS FIRETEX COLUNA 30 | G1: SHERWIN WILLIANS FIRETEX COLUNA 60 | H1: SHERWIN WILLIANS FIRETEX COLUNA 90 | I1: SHERWIN WILLIANS FIRETEX COLUNA 120 | J1: INTERNACIONAL INTERCHAR VIGA 30 | K1: INTERNACIONAL INTERCHAR VIGA 60 | L1: INTERNACIONAL INTERCHAR 90 | M1: INTERNACIONAL INTERCHAR VIGA 120 | N1: INTERNACIONAL INTERCHAR COLUNA 30 | O1: INTERNACIONAL INTERCHAR COLUNA 60 | P1: INTERNACIONAL INTERCHAR COLUNA 90 | Q1: INTERNACIONAL INTERCHAR COLUNA 120 | R1: AUDAX VIGA 30 | S1: AUDAX VIGA 60 | T1: AUDAX VIGA 90 | U1: AUDAX VIGA 120 | V1: AUDAX COLUNA 30 | W1: AUDAX COLUNA 60 | X1: AUDAX COLUNA 90 | Y1: AUDAX COLUNA 120 | Z1: JOTUN STEEALMASTER VIGA 30 | AA1: JOTUN STEEALMASTER VIGA 60 | AB1: JOTUN STEEALMASTER VIGA 90 | AC1: JOTUN STEEALMASTER VIGA 120 | AD1: JOTUN STEEALMASTER COLUNA 30 | AE1: JOTUN STEEALMASTER COLUNA 60 | AF1: JOTUN STEEALMASTER COLUNA 90 | AG1: JOTUN STEEALMASTER COLUNA 120
A2: 70 | B2: 0.181 | C2: 0.181 | D2: 0.286 | E2: 0.196 | F2: 0.174 | G2: 0.176 | H2: 0.53 | I2: 1.857 | J2: 0.135 | K2: 0.254 | L2: 0.448 | S2: 0.191 | T2: 0.46 | U2: 0.951 | X2: 0.463 | Y2: 1.511 | Z2: 0.154 | AA2: 0.154 | AB2: 0.285 | AC2: 1.147 | AD2: 0.141 | AE2: 0.176 | AF2: 0.432 | AG2: 1.235
A3: 75 | B3: 0.181 | C3: 0.181 | D3: 0.303 | E3: 0.196 | F3: 0.174 | G3: 0.184 | H3: 0.543 | I3: 1.988 | J3: 0.135 | K3: 0.26 | L3: 0.458 | S3: 0.204 | T3: 0.493 | U3: 1.031 | X3: 0.496 | Y3: 1.593 | Z3: 0.154 | AA3: 0.154 | AB3: 0.299 | AC3: 1.186 | AD3: 0.141 | AE3: 0.182 | AF3: 0.442 | AG3: 1.294
A4: 80 | B4: 0.181 | C4: 0.181 | D4: 0.32 | E4: 0.196 | F4: 0.174 | G4: 0.193 | H4: 0.556 | I4: 2.119 | J4: 0.135 | K4: 0.266 | L4: 0.469 | S4: 0.216 | T4: 0.526 | U4: 1.111 | W4: 0.214 | X4: 0.529 | Y4: 1.675 | Z4: 0.154 | AA4: 0.154 | AB4: 0.314 | AC4: 1.225 | AD4: 0.141 | AE4: 0.189 | AF4: 0.452 | AG4: 1.353
A5: 85 | B5: 0.181 | C5: 0.181 | D5: 0.337 | E5: 0.196 | F5: 0.174 | G5: 0.201 | H5: 0.568 | I5: 2.25 | J5: 0.135 | K5: 0.272 | L5: 0.479 | S5: 0.229 | T5: 0.558 | U5: 1.19 | W5: 0.241 | X5: 0.562 | Y5: 1.757 | Z5: 0.154 | AA5: 0.154 | AB5: 0.328 | AC5: 1.265 | AD5: 0.141 | AE5: 0.196 | AF5: 0.462 | AG5: 1.412
A6: 90 | B6: 0.181 | C6: 0.184 | D6: 0.354 | E6: 0.196 | F6: 0.174 | G6: 0.209 | H6: 0.581 | I6: 2.381 | J6: 0.135 | K6: 0.278 | L6: 0.489 | N6: 0.143 | O6: 0.198 | P6: 0.504 | S6: 0.242 | T6: 0.591 | U6: 1.27 | W6: 0.267 | X6: 0.595 | Y6: 1.839 | Z6: 0.154 | AA6: 0.154 | AB6: 0.342 | AC6: 1.304 | AD6: 0.141 | AE6: 0.203 | AF6: 0.473 | AG6: 1.471
A7: 95 | B7: 0.181 | C7: 0.189 | D7: 0.371 | E7: 0.196 | F7: 0.174 | G7: 0.217 | H7: 0.594 | I7: 2.505 | J7: 0.135 | K7: 0.284 | L7: 0.5 | N7: 0.143 | O7: 0.207 | P7: 0.52 | S7: 0.254 | T7: 0.624 | U7: 1.35 | W7: 0.294 | X7: 0.628 | Y7: 1.922 | Z7: 0.154 | AA7: 0.154 | AB7: 0.356 | AC7: 1.343 | AD7: 0.141 | AE7: 0.21 | AF7: 0.483 | AG7: 1.53
A8: 100 | B8: 0.181 | C8: 0.194 | D8: 0.388 | E8: 0.196 | F8: 0.174 | G8: 0.226 | H8: 0.606 | I8: 2.572 | J8: 0.135 | K8: 0.289 | L8: 0.51 | N8: 0.143 | O8: 0.215 | P8: 0.537 | S8: 0.267 | T8: 0.657 | U8: 1.429 | V8: 0.207 | W8: 0.321 | X8: 0.661 | Y8: 2.004 | Z8: 0.154 | AA8: 0.16 | AB8: 0.371 | AC8: 1.382 | AD8: 0.141 | AE8: 0.217 | AF8: 0.493 | AG8: 1.589
A9: 105 | B9: 0.181 | C9: 0.199 | D9: 0.405 | E9: 0.196 | F9: 0.174 | G9: 0.234 | H9: 0.619 | I9: 2.64 | J9: 0.135 | K9: 0.295 | L9: 0.521 | N9: 0.143 | O9: 0.224 | P9: 0.554 | S9: 0.279 | T9: 0.69 | U9: 1.509 | V9: 0.208 | W9: 0.347 | X9: 0.694 | Y9: 2.086 | Z9: 0.154 | AA9: 0.166 | AB9: 0.385 | AC9: 1.422 | AD9: 0.141 | AE9: 0.224 | AF9: 0.504 | AG9: 1.648
A10: 110 | B10: 0.181 | C10: 0.204 | D10: 0.426 | E10: 0.196 | F10: 0.174 | G10: 0.242 | H10: 0.632 | I10: 2.707 | J10: 0.135 | K10: 0.301 | L10: 0.531 | N10: 0.143 | O10: 0.233 | P10: 0.578 | S10: 0.292 | T10: 0.723 | U10: 1.589 | V10: 0.212 | W10: 0.374 | X10: 0.727 | Y10: 2.168 | Z10: 0.154 | AA10: 0.171 | AB10: 0.399 | AC10: 1.461 | AD10: 0.141 | AE10: 0.231 | AF10: 0.514 | AG10: 1.707
A11: 115 | B11: 0.181 | C11: 0.209 | D11: 0.446 | E11: 0.196 | F11: 0.174 | G11: 0.251 | H11: 0.645 | I11: 2.774 | J11: 0.135 | K11: 0.307 | L11: 0.542 | N11: 0.143 | O11: 0.242 | P11: 0.602 | S11: 0.305 | T11: 0.755 | U11: 1.668 | V11: 0.215 | W11: 0.401 | X11: 0.76 | Y11: 2.25 | Z11: 0.154 | AA11: 0.177 | AB11: 0.413 | AC11: 1.5 | AD11: 0.141 | AE11: 0.238 | AF11: 0.524 | AG11: 1.766
A12: 120 | B12: 0.181 | C12: 0.214 | D12: 0.467 | E12: 0.196 | F12: 0.174 | G12: 0.259 | H12: 0.657 | I12: 2.842 | J12: 0.135 | K12: 0.313 | L12: 0.555 | N12: 0.143 | O12: 0.25 | P12: 0.626 | S12: 0.317 | T12: 0.788 | U12: 1.748 | V12: 0.219 | W12: 0.428 | X12: 0.793 | Y12: 2.332 | Z12: 0.154 | AA12: 0.183 | AB12: 0.428 | AC12: 1.539 | AD12: 0.141 | AE12: 0.244 | AF12: 0.534 | AG12: 1.825
A13: 125 | B13: 0.181 | C13: 0.219 | D13: 0.487 | E13: 0.196 | F13: 0.174 | G13: 0.267 | H13: 0.67 | I13: 2.909 | J13: 0.135 | K13: 0.319 | L13: 0.579 | N13: 0.143 | O13: 0.259 | P13: 0.65 | S13: 0.33 | T13: 0.821 | U13: 1.82 | V13: 0.223 | W13: 0.454 | X13: 0.826 | Y13: 2.414 | Z13: 0.154 | AA13: 0.189 | AB13: 0.445 | AC13: 1.579 | AD13: 0.141 | AE13: 0.251 | AF13: 0.545 | AG13: 1.884
A14: 130 | B14: 0.181 | C14: 0.223 | D14: 0.508 | E14: 0.196 | F14: 0.174 | G14: 0.275 | H14: 0.683 | I14: 2.976 | J14: 0.135 | K14: 0.325 | L14: 0.603 | N14: 0.143 | O14: 0.268 | P14: 0.674 | S14: 0.342 | T14: 0.854 | U14: 1.874 | V14: 0.226 | W14: 0.481 | X14: 0.859 | Y14: 2.496 | Z14: 0.154 | AA14: 0.194 | AB14: 0.463 | AC14: 1.618 | AD14: 0.141 | AE14: 0.258 | AF14: 0.555 | AG14: 1.943
A15: 135 | B15: 0.181 | C15: 0.228 | D15: 0.528 | E15: 0.196 | F15: 0.174 | G15: 0.284 | H15: 0.696 | I15: 3.043 | J15: 0.135 | K15: 0.33 | L15: 0.628 | N15: 0.143 | O15: 0.276 | P15: 0.698 | S15: 0.355 | T15: 0.887 | U15: 1.928 | V15: 0.23 | W15: 0.508 | X15: 0.892 | Y15: 2.578 | Z15: 0.154 | AA15: 0.2 | AB15: 0.481 | AC15: 1.657 | AD15: 0.141 | AE15: 0.265 | AF15: 0.565 | AG15: 2.002
A16: 140 | B16: 0.181 | C16: 0.233 | D16: 0.549 | E16: 0.196 | F16: 0.174 | G16: 0.292 | H16: 0.708 | I16: 3.111 | J16: 0.135 | K16: 0.336 | L16: 0.652 | N16: 0.143 | O16: 0.285 | P16: 0.722 | S16: 0.368 | T16: 0.92 | U16: 1.982 | V16: 0.234 | W16: 0.534 | X16: 0.925 | Y16: 2.66 | Z16: 0.154 | AA16: 0.206 | AB16: 0.499 | AC16: 1.696 | AD16: 0.141 | AE16: 0.272 | AF16: 0.575 | AG16: 2.06
A17: 145 | B17: 0.181 | C17: 0.238 | D17: 0.569 | E17: 0.196 | F17: 0.174 | G17: 0.3 | H17: 0.721 | I17: 3.178 | J17: 0.135 | K17: 0.342 | L17: 0.676 | N17: 0.143 | O17: 0.294 | P17: 0.746 | S17: 0.38 | T17: 0.953 | U17: 2.035 | V17: 0.237 | W17: 0.561 | X17: 0.958 | Y17: 2.743 | Z17: 0.154 | AA17: 0.212 | AB17: 0.517 | AC17: 1.736 | AD17: 0.141 | AE17: 0.279 | AF17: 0.586 | AG17: 2.119
A18: 150 | B18: 0.181 | C18: 0.243 | D18: 0.592 | E18: 0.196 | F18: 0.174 | G18: 0.309 | H18: 0.734 | I18: 3.245 | J18: 0.135 | K18: 0.348 | L18: 0.7 | N18: 0.143 | O18: 0.303 | P18: 0.77 | S18: 0.393 | T18: 0.985 | U18: 2.089 | V18: 0.241 | W18: 0.588 | X18: 0.991 | Y18: 2.825 | Z18: 0.154 | AA18: 0.217 | AB18: 0.535 | AC18: 1.775 | AD18: 0.141 | AE18: 0.286 | AF18: 0.596 | AG18: 2.178
A19: 155 | B19: 0.181 | C19: 0.248 | D19: 0.618 | E19: 0.196 | F19: 0.174 | G19: 0.317 | H19: 0.747 | I19: 3.313 | J19: 0.135 | K19: 0.354 | L19: 0.725 | N19: 0.143 | O19: 0.311 | P19: 0.794 | S19: 0.405 | T19: 1.018 | U19: 2.143 | V19: 0.245 | W19: 0.615 | X19: 1.024 | Y19: 2.907 | Z19: 0.154 | AA19: 0.223 | AB19: 0.553 | AC19: 1.814 | AD19: 0.141 | AE19: 0.293 | AF19: 0.606 | AG19: 2.237
... A22: 170 | B22: 0.181 | C22: 0.263 | D22: 0.673 | E22: 0.196 | F22: 0.174 | G22: 0.342 | H22: 0.785 | I22: 3.511 | J22: 0.135 | K22: 0.371 | L22: 0.798 | N22: 0.143 | O22: 0.337 | P22: 0.866 | S22: 0.443 | T22: 1.117 | U22: 2.304 | V22: 0.256 | W22: 0.664 | X22: 1.124 | Y22: 3.153 | Z22: 0.154 | AA22: 0.24 | AB22: 0.607 | AC22: 1.932 | AD22: 0.141 | AE22: 0.313 | AF22: 0.639 | AG22: 2.414
A23: 175 | B23: 0.181 | C23: 0.267 | D23: 0.695 | E23: 0.196 | F23: 0.174 | G23: 0.35 | H23: 0.798 | I23: 3.569 | J23: 0.135 | K23: 0.377 | L23: 0.822 | N23: 0.143 | O23: 0.346 | P23: 0.89 | S23: 0.456 | U23: 2.358 | V23: 0.259 | W23: 0.679 | X23: 1.157 | Y23: 3.235 | Z23: 0.154 | AA23: 0.246 | AB23: 0.625 | AC23: 1.971 | AD23: 0.141 | AE23: 0.32 | AF23: 0.65 | AG23: 2.473
A24: 180 | B24: 0.181 | C24: 0.272 | D24: 0.716 | E24: 0.196 | F24: 0.174 | G24: 0.358 | H24: 0.81 | I24: 3.626 | J24: 0.135 | K24: 0.383 | L24: 0.846 | N24: 0.143 | O24: 0.355 | P24: 0.914 | S24: 0.469 | U24: 2.411 | V24: 0.263 | W24: 0.695 | X24: 1.19 | Y24: 3.317 | Z24: 0.154 | AA24: 0.252 | AC24: 2.01 | AD24: 0.141 | AE24: 0.327 | AF24: 0.661 | AG24: 2.542
A25: 185 | B25: 0.181 | C25: 0.277 | D25: 0.737 | E25: 0.196 | F25: 0.174 | G25: 0.367 | H25: 0.823 | I25: 3.684 | J25: 0.135 | K25: 0.389 | L25: 0.871 | N25: 0.143 | O25: 0.364 | P25: 0.938 | S25: 0.481 | U25: 2.465 | V25: 0.267 | W25: 0.71 | X25: 1.223 | Y25: 3.399 | Z25: 0.154 | AA25: 0.258 | AC25: 2.05 | AD25: 0.141 | AE25: 0.334 | AF25: 0.672 | AG25: 2.633
A26: 190 | B26: 0.181 | C26: 0.282 | D26: 0.758 | E26: 0.196 | F26: 0.174 | G26: 0.375 | H26: 0.736 | I26: 3.741 | J26: 0.135 | K26: 0.395 | L26: 0.895 | N26: 0.143 | O26: 0.372 | P26: 0.962 | S26: 0.494 | U26: 2.519 | V26: 0.27 | W26: 0.726 | X26: 1.256 | Y26: 3.478 | Z26: 0.154 | AA26: 0.263 | AC26: 2.089 | AD26: 0.141 | AE26: 0.341 | AF26: 0.683 | AG26: 2.724
A27: 195 | B27: 0.181 | C27: 0.287 | D27: 0.779 | E27: 0.196 | F27: 0.174 | G27: 0.383 | H27: 0.849 | I27: 3.799 | J27: 0.135 | K27: 0.401 | L27: 0.919 | N27: 0.143 | O27: 0.381 | P27: 0.986 | S27: 0.506 | U27: 2.573 | V27: 0.274 | W27: 0.741 | Y27: 3.52 | Z27: 0.154 | AA27: 0.269 | AC27: 2.128 | AD27: 0.141 | AE27: 0.348 | AF27: 0.694 | AG27: 2.815
A28: 200 | B28: 0.181 | C28: 0.292 | D28: 0.801 | E28: 0.196 | F28: 0.174 | G28: 0.392 | H28: 0.861 | I28: 3.856 | J28: 0.135 | K28: 0.406 | L28: 0.943 | N28: 0.143 | O28: 0.39 | P28: 1.009 | S28: 0.519 | U28: 2.626 | V28: 0.278 | W28: 0.757 | Y28: 3.562 | Z28: 0.154 | AA28: 0.275 | AC28: 2.167 | AD28: 0.141 | AE28: 0.354 | AF28: 0.705 | AG28: 2.906
A29: 205 | B29: 0.181 | C29: 0.297 | D29: 0.822 | E29: 0.196 | F29: 0.174 | G29: 0.4 | H29: 0.874 | I29: 3.914 | J29: 0.135 | K29: 0.412 | L29: 0.963 | N29: 0.143 | O29: 0.398 | P29: 1.033 | S29: 0.532 | U29: 2.68 | V29: 0.281 | W29: 0.773 | Y29: 3.603 | Z29: 0.154 | AA29: 0.281 | AC29: 2.207 | AD29: 0.141 | AE29: 0.361 | AG29: 2.997
A30: 210 | B30: 0.181 | C30: 0.302 | D30: 0.843 | E30: 0.196 | F30: 0.174 | G30: 0.408 | I30: 3.971 | J30: 0.135 | K30: 0.418 | L30: 0.992 | N30: 0.143 | O30: 0.407 | P30: 1.057 | R30: 0.18 | S30: 0.544 | U30: 2.734 | V30: 0.285 | W30: 0.788 | Y30: 3.645 | Z30: 0.154 | AA30: 0.286 | AC30: 2.246 | AD30: 0.141 | AE30: 0.368 | AG30: 3.088
A31: 215 | B31: 0.181 | C31: 0.307 | D31: 0.864 | E31: 0.196 | F31: 0.174 | G31: 0.416 | I31: 4.029 | J31: 0.135 | K31: 0.424 | L31: 1.016 | N31: 0.143 | O31: 0.416 | P31: 1.081 | R31: 0.186 | S31: 0.557 | U31: 2.787 | V31: 0.289 | W31: 0.804 | Y31: 3.687 | Z31: 0.154 | AA31: 0.292 | AC31: 2.285 | AD31: 0.141 | AE31: 0.375 | AG31: 3.179
A32: 220 | B32: 0.181 | C32: 0.311 | D32: 0.886 | E32: 0.196 | F32: 0.174 | G32: 0.425 | I32: 4.087 | J32: 0.135 | K32: 0.43 | L32: 1.041 | N32: 0.143 | O32: 0.425 | P32: 1.105 | R32: 0.192 | S32: 0.569 | U32: 2.841 | V32: 0.292 | W32: 0.822 | Y32: 3.729 | Z32: 0.154 | AA32: 0.298 | AC32: 2.324 | AD32: 0.141 | AE32: 0.382 | AG32: 3.269
A33: 225 | B33: 0.181 | C33: 0.316 | E33: 0.196 | F33: 0.174 | G33: 0.433 | I33: 4.144 | J33: 0.135 | K33: 0.436 | L33: 1.065 | N33: 0.143 | O33: 0.433 | P33: 1.129 | R33: 0.198 | S33: 0.582 | U33: 2.895 | V33: 0.296 | W33: 0.842 | Y33: 3.771 | Z33: 0.154 | AA33: 0.304 | AC33: 2.364 | AD33: 0.141 | AE33: 0.389 | AG33: 3.36
A34: 230 | B34: 0.181 | C34: 0.321 | E34: 0.196 | F34: 0.174 | G34: 0.441 | I34: 4.202 | J34: 0.135 | K34: 0.442 | L34: 1.089 | N34: 0.143 | O34: 0.442 | R34: 0.203 | S34: 0.595 | U34: 2.949 | V34: 0.3 | W34: 0.861 | Y34: 3.813 | Z34: 0.154 | AA34: 0.309 | AC34: 2.403 | AD34: 0.141 | AE34: 0.396 | AG34: 3.451
A35: 235 | B35: 0.181 | C35: 0.326 | E35: 0.196 | F35: 0.174 | G35: 0.45 | I35: 4.259 | J35: 0.136 | K35: 0.447 | L35: 1.114 | N35: 0.143 | O35: 0.451 | R35: 0.209 | S35: 0.607 | U35: 3.002 | V35: 0.303 | W35: 0.881 | Y35: 3.855 | Z35: 0.154 | AA35: 0.315 | AC35: 2.442 | AD35: 0.141 | AE35: 0.403 | AG35: 3.542
A36: 240 | B36: 0.181 | C36: 0.331 | E36: 0.196 | F36: 0.174 | G36: 0.458 | I36: 4.317 | J36: 0.14 | K36: 0.453 | L36: 1.138 | N36: 0.143 | O36: 0.459 | R36: 0.215 | S36: 0.62 | U36: 3.056 | V36: 0.307 | W36: 0.901 | Y36: 3.897 | Z36: 0.154 | AA36: 0.321 | AC36: 2.481 | AD36: 0.141 | AE36: 0.409 | AG36: 3.633
A37: 245 | B37: 0.181 | C37: 0.336 | E37: 0.196 | F37: 0.174 | G37: 0.466 | I37: 4.374 | J37: 0.143 | K37: 0.459 | L37: 1.162 | N37: 0.143 | O37: 0.468 | R37: 0.221 | S37: 0.66 | U37: 3.111 | V37: 0.311 | W37: 0.921 | Y37: 3.939 | Z37: 0.154 | AA37: 0.326 | AC37: 2.523 | AD37: 0.141 | AE37: 0.416 | AG37: 3.724
A38: 250 | B38: 0.181 | C38: 0.341 | E38: 0.196 | F38: 0.174 | G38: 0.474 | I38: 4.432 | J38: 0.147 | K38: 0.465 | N38: 0.143 | O38: 0.477 | R38: 0.227 | S38: 0.81 | U38: 3.173 | V38: 0.313 | W38: 0.94 | Y38: 3.981 | Z38: 0.154 | AA38: 0.332 | AC38: 2.584 | AD38: 0.141 | AE38: 0.423 | AG38: 3.815
A39: 255 | B39: 0.181 | C39: 0.346 | E39: 0.197 | F39: 0.174 | G39: 0.483 | I39: 4.489 | J39: 0.15 | K39: 0.471 | N39: 0.143 | O39: 0.486 | R39: 0.232 | S39: 0.82 | U39: 3.325 | V39: 0.316 | W39: 0.96 | Y39: 4.023 | Z39: 0.154 | AA39: 0.338 | AC39: 2.646 | AD39: 0.141 | AE39: 0.434 | AG39: 3.906
A40: 260 | B40: 0.181 | C40: 0.351 | E40: 0.204 | F40: 0.174 | G40: 0.491 | I40: 4.547 | J40: 0.154 | K40: 0.477 | N40: 0.143 | O40: 0.494 | R40: 0.238 | S40: 0.83 | U40: 3.297 | V40: 0.319 | W40: 0.98 | Y40: 4.064 | Z40: 0.154 | AA40: 0.344 | AC40: 2.707 | AD40: 0.141 | AE40: 0.446 | AG40: 3.997
A41: 265 | B41: 0.181 | C41: 0.356 | E41: 0.21 | F41: 0.174 | G41: 0.499 | I41: 4.604 | J41: 0.158 | K41: 0.483 | N41: 0.143 | O41: 0.503 | R41: 0.244 | S41: 0.841 | U41: 3.359 | V41: 0.322 | W41: 1 | Y41: 4.156 | Z41: 0.154 | AA41: 0.349 | AC41: 2.768 | AD41: 0.141 | AE41: 0.457 | AG41: 4.063
A42: 270 | B42: 0.181 | C42: 0.36 | E42: 0.217 | F42: 0.174 | G42: 0.508 | I42: 4.662 | J42: 0.161 | K42: 0.488 | N42: 0.143 | O42: 0.512 | R42: 0.25 | S42: 0.851 | U42: 3.421 | V42: 0.325 | W42: 1.02 | Y42: 4.365 | Z42: 0.154 | AA42: 0.355 | AC42: 2.83 | AD42: 0.141 | AE42: 0.468 | AG42: 4.112
...

Sheet PERFIS PADRÃO
B2: BIBLIOTECA DE PERFIS METALICOS
B3: BITOLA | C3: d (mm) | D3: bf (mm) | E3: tw (mm) | F3: tf (mm) | G3: h (mm) | H3: d' (mm) | I3: PERIMETRO (mm) | J3: PERÍMETRO (m) | K3: PESO (kg)
B4: HP200x53,0 | C4: 204 | D4: 207 | E4: 11.3 | F4: 11.3 | G4: 181.4 | H4: 161 | I4: =(2*C4)+(3*D4)-(2*E4) -> 1006.4 | J4: =I4/1000 -> 1.0064 | K4: 53
B5: HP250x62,0 | C5: 246 | D5: 256 | E5: 10.5 | F5: 10.7 | G5: 225 | H5: 201 | I5: =(2*C5)+(3*D5)-(2*E5) -> 1239 | J5: =I5/1000 -> 1.239 | K5: 62
B6: HP250x85,0 | C6: 254 | D6: 260 | E6: 14.4 | F6: 14.4 | G6: 225.2 | H6: 201 | I6: =(2*C6)+(3*D6)-(2*E6) -> 1259.2 | J6: =I6/1000 -> 1.2592 | K6: 85
B7: HP310x110,0 | C7: 308 | D7: 310 | E7: 15.4 | F7: 15.5 | G7: 277.2 | H7: 245 | I7: =(2*C7)+(3*D7)-(2*E7) -> 1515.2 | J7: =I7/1000 -> 1.5152 | K7: 110
B8: HP310x125,0 | C8: 312 | D8: 312 | E8: 17.4 | F8: 17.4 | G8: 277.2 | H8: 245 | I8: =(2*C8)+(3*D8)-(2*E8) -> 1525.2 | J8: =I8/1000 -> 1.5252 | K8: 125
B9: HP310x79,0 | C9: 299 | D9: 306 | E9: 11 | F9: 11 | G9: 277 | H9: 245 | I9: =(2*C9)+(3*D9)-(2*E9) -> 1494 | J9: =I9/1000 -> 1.494 | K9: 79
B10: HP310x93,0 | C10: 303 | D10: 308 | E10: 13.1 | F10: 13.1 | G10: 276.8 | H10: 245 | I10: =(2*C10)+(3*D10)-(2*E10) -> 1503.8 | J10: =I10/1000 -> 1.5038 | K10: 93
B11: I1000x250x13x16 | C11: 1000 | D11: 250 | E11: 13 | F11: 16 | I11: =(2*C11)+(3*D11)-(2*E11) -> 2724 | J11: =I11/1000 -> 2.724
B12: I1000x250x16x19 | C12: 1000 | D12: 250 | E12: 16 | F12: 18 | I12: =(2*C12)+(3*D12)-(2*E12) -> 2718 | J12: =I12/1000 -> 2.718
B13: I1000x275x13x16 | C13: 1000 | D13: 275 | E13: 13 | F13: 16 | I13: =(2*C13)+(3*D13)-(2*E13) -> 2799 | J13: =I13/1000 -> 2.799
B14: I1000x275x13x19 | C14: 1000 | D14: 275 | E14: 13 | F14: 19 | I14: =(2*C14)+(3*D14)-(2*E14) -> 2799 | J14: =I14/1000 -> 2.799
B15: I1000x300x13x13 | C15: 1000 | D15: 300 | E15: 13 | F15: 13 | J15: =I15/1000 -> 0
B16: I1000x300x13x16 | C16: 1000 | D16: 300 | E16: 13 | F16: =RIGHT(B16,2) -> 16 | J16: =I16/1000 -> 0
B17: I1000x300x13x19 | C17: 1000 | D17: 300 | E17: 13 | F17: =RIGHT(B17,2) -> 19 | J17: =I17/1000 -> 0
B18: I1000x300x13x22 | C18: 1000 | D18: 300 | E18: 13 | F18: =RIGHT(B18,2) -> 22 | J18: =I18/1000 -> 0
B19: I1000x300x13x25 | C19: 1000 | D19: 300 | E19: 13 | F19: =RIGHT(B19,2) -> 25 | J19: =I19/1000 -> 0
B20: I1000x300x13x32 | C20: 1000 | D20: 300 | E20: 13 | F20: =RIGHT(B20,2) -> 32 | J20: =I20/1000 -> 0
B21: I1000x300x16x10 | C21: 1000 | D21: 300 | E21: 16 | F21: 10 | G21: 968 | I21: =(2*C21)+(3*D21)-(2*E21) -> 2868 | J21: =I21/1000 -> 2.868
B22: I1000x300x16x25 | C22: 1000 | D22: 300 | E22: 16 | F22: 25 | I22: =(2*C22)+(3*D22)-(2*E22) -> 2868 | J22: =I22/1000 -> 2.868
B23: I1000x375x19x32 | C23: 1000 | D23: 375 | E23: 19 | F23: =RIGHT(B23,2) -> 32 | J23: =I23/1000 -> 0
B24: I1000x375x25x13 | C24: 1000 | D24: 375 | E24: 25 | F24: 13 | G24: 950 | I24: =(2*C24)+(3*D24)-(2*E24) -> 3075 | J24: =I24/1000 -> 3.075
B25: I1000x375x32x13 | C25: 1000 | D25: 375 | E25: 32 | F25: 13 | G25: 936 | I25: =(2*C25)+(3*D25)-(2*E25) -> 3061 | J25: =I25/1000 -> 3.061
B26: I1000x400x38x19 | C26: 1000 | D26: 400 | E26: 38 | F26: 19 | G26: 924 | I26: =(2*C26)+(3*D26)-(2*E26) -> 3124 | J26: =I26/1000 -> 3.124
B27: I1000x450x38x22 | C27: 1000 | D27: 450 | E27: 38 | F27: 22 | G27: 924 | I27: =(2*C27)+(3*D27)-(2*E27) -> 3274 | J27: =I27/1000 -> 3.274
B28: I1100x375x13x32 | C28: 1100 | D28: 375 | E28: 13 | F28: =RIGHT(B28,2) -> 32 | J28: =I28/1000 -> 0
B29: I1100x375x19x32 | C29: 1100 | D29: 375 | E29: 19 | F29: =RIGHT(B29,2) -> 32 | J29: =I29/1000 -> 0
B30: I1300x200x13x10 | C30: 1300 | D30: 200 | E30: 13 | F30: 10 | G30: 1274 | I30: =(2*C30)+(3*D30)-(2*E30) -> 3174 | J30: =I30/1000 -> 3.174
B31: I350x330x13x10 | C31: 350 | D31: 330 | E31: 13 | F31: 10 | G31: 324 | I31: =(2*C31)+(3*D31)-(2*E31) -> 1664 | J31: =I31/1000 -> 1.664
B32: I350x375x22x13 | C32: 350 | D32: 375 | E32: 22 | F32: 13 | G32: 306 | I32: =(2*C32)+(3*D32)-(2*E32) -> 1781 | J32: =I32/1000 -> 1.781
B33: I375x375x3x12 | C33: 375 | D33: 375 | E33: 3.75 | F33: 12.7 | I33: =(2*C33)+(3*D33)-(2*E33) -> 1867.5 | J33: =I33/1000 -> 1.8675
B34: I375x375x3x12 | C34: 375 | D34: 375 | E34: 3.75 | F34: 12.7 | I34: =(2*C34)+(3*D34)-(2*E34) -> 1867.5 | J34: =I34/1000 -> 1.8675
B35: I375x375x3x12 | C35: 375 | D35: 375 | E35: 3.75 | F35: 12.7 | I35: =(2*C35)+(3*D35)-(2*E35) -> 1867.5 | J35: =I35/1000 -> 1.8675
B36: I375x375x3x12 | C36: 375 | D36: 375 | E36: 3.75 | F36: 12.7 | I36: =(2*C36)+(3*D36)-(2*E36) -> 1867.5 | J36: =I36/1000 -> 1.8675
B37: I375x375x3x12 | C37: 375 | D37: 375 | E37: 3.75 | F37: 12.7 | I37: =(2*C37)+(3*D37)-(2*E37) -> 1867.5 | J37: =I37/1000 -> 1.8675
B38: I375x375x3x12 | C38: 375 | D38: 375 | E38: 3.75 | F38: 12.7 | I38: =(2*C38)+(3*D38)-(2*E38) -> 1867.5 | J38: =I38/1000 -> 1.8675
B39: I375x375x3x12 | C39: 375 | D39: 375 | E39: 3.75 | F39: 12.7 | I39: =(2*C39)+(3*D39)-(2*E39) -> 1867.5 | J39: =I39/1000 -> 1.8675
B40: I375x375x3x12 | C40: 375 | D40: 375 | E40: 3.75 | F40: 12.7 | I40: =(2*C40)+(3*D40)-(2*E40) -> 1867.5 | J40: =I40/1000 -> 1.8675
B41: I375x375x3x12 | C41: 375 | D41: 375 | E41: 3.75 | F41: 12.7 | I41: =(2*C41)+(3*D41)-(2*E41) -> 1867.5 | J41: =I41/1000 -> 1.8675
...

Sheet PERFIS GERDAU
A1: BITOLA | B1: MASSA LINEAR | C1: d | D1: bf | E1: ESPESSURA | G1: h | H1: d’ | I1: ÁREA | J1: PERIMETRO | K1: EIXO X-X | O1: EIXO Y-Y | S1: rt | T1: It | U1: ESBELTEZ | X1: Cw | Z1: ÁREA REDUZIDA | AA1: *CARGA ADM EST | AB1: *CARGA ADM EST | AC1: BITOLA
E2: tw | F2: tf | J2: u | K2: Ix | L2: Wx | M2: rx | N2: Zx | O2: Iy | P2: Wy | Q2: ry | R2: Zy | U2: ABA - λf | V2: ABA - λw | W2: Coef Red. Q | AA2: (Q.A's.fy)/1,66 | AB2: (Q.A's.fy)/2,00
A3: mm x kg/m | B3: kg/mL | C3: mm | D3: mm | E3: mm | F3: mm | G3: mm | H3: mm | I3: cm² | J3: cm | K3: cm⁴ | L3: cm³ | M3: cm | N3: cm³ | O3: cm⁴ | P3: cm³ | Q3: cm | R3: cm³ | S3: cm | T3: cm⁴ | U3: bf/2t | V3: d’/t | W3: ≤ 1,00 | X3: cm⁶ | Y3: m³/m | Z3: cm² | AA3: tf | AB3: tf | AC3: mm x kg/m
A4: W 150 x 13,0 | B4: 13 | C4: 148 | D4: 100 | E4: 4.3 | F4: 4.9 | G4: 138 | H4: 118 | I4: 16.6 | J4: 67 | K4: 635 | L4: 85.8 | M4: 6.18 | N4: 96.4 | O4: 82 | P4: 16.4 | Q4: 2.22 | R4: 25.5 | S4: 2.6 | T4: 1.72 | U4: 10.2 | V4: 27.49 | W4: 1 | X4: 4.181 | Y4: 0.67 | Z4: =AA4/2.1 -> 6.6666667 | AA4: 14 | AB4: 11.2 | AC4: W 150 x 13,0
A5: W 150 x 18,0 | B5: 18 | C5: 153 | D5: 102 | E5: 5.8 | F5: 7.1 | G5: 139 | H5: 119 | I5: 23.4 | J5: 69 | K5: 939 | L5: 122.8 | M5: 6.34 | N5: 139.4 | O5: 126 | P5: 24.7 | Q5: 2.32 | R5: 38.5 | S5: 2.69 | T5: 4.34 | U5: 7.18 | V5: 20.48 | W5: 1 | X5: 6.683 | Y5: 0.69 | Z5: =AA5/2.1 -> 13.333333 | AA5: 28 | AB5: 22.4 | AC5: W 150 x 18,0
A6: W 150 x 22,5 (H) | B6: 22.5 | C6: 152 | D6: 152 | E6: 5.8 | F6: 6.6 | G6: 139 | H6: 119 | I6: 29 | J6: 88 | K6: 1229 | L6: 161.7 | M6: 6.51 | N6: 179.6 | O6: 387 | P6: 50.9 | Q6: 3.65 | R6: 77.9 | S6: 4.1 | T6: 4.75 | U6: 11.52 | V6: 20.48 | W6: 1 | X6: 20.417 | Y6: 0.88 | Z6: =AA6/2.1 -> 15.714286 | AA6: 33 | AB6: 26.4 | AC6: W 150 x 22,5 (H)
A7: W 150 x 24,0 | B7: 24 | C7: 160 | D7: 102 | E7: 6.6 | F7: 10.3 | G7: 139 | H7: 115 | I7: 31.5 | J7: 69 | K7: 1384 | L7: 173 | M7: 6.63 | N7: 197.6 | O7: 183 | P7: 35.9 | Q7: 2.41 | R7: 55.8 | S7: 2.73 | T7: 11.08 | U7: 4.95 | V7: 17.48 | W7: 1 | X7: 10.206 | Y7: 0.69 | Z7: =AA7/2.1 -> 20.952381 | AA7: 44 | AB7: 35.2 | AC7: W 150 x 24,0
A8: W 150 x 29,8 (H) | B8: 29.8 | C8: 157 | D8: 153 | E8: 6.6 | F8: 9.3 | G8: 138 | H8: 118 | I8: 38.5 | J8: 90 | K8: 1739 | L8: 221.5 | M8: 6.72 | N8: 247.5 | O8: 556 | P8: 72.6 | Q8: 3.8 | R8: 110.8 | S8: 4.18 | T8: 10.95 | U8: 8.23 | V8: 17.94 | W8: 1 | X8: 30.277 | Y8: 0.9 | Z8: =AA8/2.1 -> 25.238095 | AA8: 53 | AB8: 42.4 | AC8: W 150 x 29,8 (H)
A9: W 150 x 37,1 (H) | B9: 37.1 | C9: 162 | D9: 154 | E9: 8.1 | F9: 11.6 | G9: 139 | H9: 119 | I9: 47.8 | J9: 91 | K9: 2244 | L9: 277 | M9: 6.85 | N9: 313.5 | O9: 707 | P9: 91.8 | Q9: 3.84 | R9: 140.4 | S9: 4.22 | T9: 20.58 | U9: 6.64 | V9: 14.67 | W9: 1 | X9: 39.93 | Y9: 0.91 | Z9: =AA9/2.1 -> 34.285714 | AA9: 72 | AB9: 57.6 | AC9: W 150 x 37,1 (H)
A10: W 200 x 15,0 | B10: 15 | C10: 200 | D10: 100 | E10: 4.3 | F10: 5.2 | G10: 190 | H10: 170 | I10: 19.4 | J10: 77 | K10: 1305 | L10: 130.5 | M10: 8.2 | N10: 147.9 | O10: 87 | P10: 17.4 | Q10: 2.12 | R10: 27.3 | S10: 2.55 | T10: 2.05 | U10: 9.62 | V10: 39.44 | W10: 0.95 | X10: 8.222 | Y10: 0.77 | Z10: =AA10/2.1 -> 7.6190476 | AA10: 16 | AB10: 12.8 | AC10: W 200 x 15,0
A11: W 200 x 19,3 | B11: 19.3 | C11: 203 | D11: 102 | E11: 5.8 | F11: 6.5 | G11: 190 | H11: 170 | I11: 25.1 | J11: 79 | K11: 1686 | L11: 166.1 | M11: 8.19 | N11: 190.6 | O11: 116 | P11: 22.7 | Q11: 2.14 | R11: 35.9 | S11: 2.59 | T11: 4.02 | U11: 7.85 | V11: 29.31 | W11: 1 | X11: 11.098 | Y11: 0.79 | Z11: =AA11/2.1 -> 13.333333 | AA11: 28 | AB11: 22.4 | AC11: W 200 x 19,3
A12: W 200 x 22,5 | B12: 22.5 | C12: 206 | D12: 102 | E12: 6.2 | F12: 8 | G12: 190 | H12: 170 | I12: 29 | J12: 79 | K12: 2029 | L12: 197 | M12: 8.37 | N12: 225.5 | O12: 142 | P12: 27.9 | Q12: 2.22 | R12: 43.9 | S12: 2.63 | T12: 6.18 | U12: 6.38 | V12: 27.42 | W12: 1 | X12: 13.868 | Y12: 0.79 | Z12: =AA12/2.1 -> 17.142857 | AA12: 36 | AB12: 28.8 | AC12: W 200 x 22,5
A13: W 200 x 26,6 | B13: 26.6 | C13: 207 | D13: 133 | E13: 5.8 | F13: 8.4 | G13: 190 | H13: 170 | I13: 34.2 | J13: 92 | K13: 2611 | L13: 252.3 | M13: 8.73 | N13: 282.3 | O13: 330 | P13: 49.6 | Q13: 3.1 | R13: 76.3 | S13: 3.54 | T13: 7.65 | U13: 7.92 | V13: 29.34 | W13: 1 | X13: 32.477 | Y13: 0.92 | Z13: =AA13/2.1 -> 20.47619 | AA13: 43 | AB13: 34.4 | AC13: W 200 x 26,6
A14: W 200 x 31,3 | B14: 31.3 | C14: 210 | D14: 134 | E14: 6.4 | F14: 10.2 | G14: 190 | H14: 170 | I14: 40.3 | J14: 93 | K14: 3168 | L14: 301.7 | M14: 8.86 | N14: 338.6 | O14: 410 | P14: 61.2 | Q14: 3.19 | R14: 94 | S14: 3.6 | T14: 12.59 | U14: 6.57 | V14: 26.5 | W14: 1 | X14: 40.822 | Y14: 0.93 | Z14: =AA14/2.1 -> 26.666667 | AA14: 56 | AB14: 44.8 | AC14: W 200 x 31,3
A15: W 200 x 35,9 (H) | B15: 35.9 | C15: 201 | D15: 165 | E15: 6.2 | F15: 10.2 | G15: 181 | H15: 161 | I15: 45.7 | J15: 103 | K15: 3437 | L15: 342 | M15: 8.67 | N15: 379.2 | O15: 764 | P15: 92.6 | Q15: 4.09 | R15: 141 | S15: 4.5 | T15: 14.51 | U15: 8.09 | V15: 25.9 | W15: 1 | X15: 69.502 | Y15: 1.03 | Z15: =AA15/2.1 -> 30.47619 | AA15: 64 | AB15: 51.2 | AC15: W 200 x 35,9 (H)
... A91: W 610 x 174,0 | B91: 174 | C91: 616 | D91: 325 | E91: 14 | F91: 21.6 | G91: 573 | H91: 541 | I91: 222.8 | J91: 248 | K91: 147754 | L91: 4797.2 | M91: 25.75 | N91: 5383.3 | O91: 12374 | P91: 761.5 | Q91: 7.45 | R91: 1171.1 | S91: 8.58 | T91: 286.88 | U91: 7.52 | V91: 38.63 | W91: 0.96 | X91: 10915665 | Y91: 2.48 | Z91: =AA91/2.1 -> 180 | AA91: 378 | AB91: 302.4 | AC91: W 610 x 174,0

Sheet PERFIS
A1: PERFIL | B1: d | C1: bf | D1: tw | E1: tf | F1: kg/m
A2: CS 150 x 25 | B2: 150 | C2: 150 | D2: 6.3 | E2: 8 | F2: 25.4 | I2: TIPO
A3: CS 150 x 29 | B3: 150 | C3: 150 | D3: 6.3 | E3: 9.5 | F3: 28.9 | I3: VIGA
A4: CS 150 x 31 | B4: 150 | C4: 150 | D4: 8 | E4: 9.5 | F4: 30.6 | I4: COLUNA
A5: CS 150 x 37 | B5: 150 | C5: 150 | D5: 8 | E5: 12.5 | F5: 37.3 | I5: TUBOS
A6: CS 150 x 45 | B6: 150 | C6: 150 | D6: 8 | E6: 16 | F6: 45.1 | I6: OUTROS
A7: CS 200 x 29 | B7: 200 | C7: 200 | D7: 6.3 | E7: 6.3 | F7: 29
A8: CS 200 x 34 | B8: 200 | C8: 200 | D8: 6.3 | E8: 8 | F8: 34.2
A9: CS 200 x 39 | B9: 200 | C9: 200 | D9: 6.3 | E9: 9.5 | F9: 38.8
A10: CS 200 x 41 | B10: 200 | C10: 200 | D10: 8 | E10: 9.5 | F10: 41.2
A11: CS 200 x 50 | B11: 200 | C11: 200 | D11: 8 | E11: 12.5 | F11: 50.2
A12: CS 200 x 61 | B12: 200 | C12: 200 | D12: 8 | E12: 16 | F12: 60.8
A13: CS 250 x 108 | B13: 250 | C13: 250 | D13: 12.5 | E13: 22.4 | F13: 108
A14: CS 250 x 43 | B14: 250 | C14: 250 | D14: 6.3 | E14: 8 | F14: 42.9
A15: CS 250 x 49 | B15: 250 | C15: 250 | D15: 6.3 | E15: 9.5 | F15: 48.7
A16: CS 250 x 52 | B16: 250 | C16: 250 | D16: 8 | E16: 9.5 | F16: 51.8
A17: CS 250 x 63 | B17: 250 | C17: 250 | D17: 8 | E17: 12.5 | F17: 63.2
A18: CS 250 x 66 | B18: 250 | C18: 250 | D18: 9.5 | E18: 12.5 | F18: 65.9
... A560: PERFIL | B560: 0 | C560: 0 | D560: 0 | E560: 0 | F560: 0

Sheet VIGAS 30
A1: Hp/A | B1: ESP | D1: y = 0,0012x - 0,0742
A2: 210 | B2: 0.18 | C2: =A2*0.0012-0.0742 -> 0.1778 | D2: =C2-B2 -> -0.0022
A3: 215 | B3: 0.186 | C3: =A3*0.0012-0.0742 -> 0.1838 | D3: =C3-B3 -> -0.0022
A4: 220 | B4: 0.192 | C4: =A4*0.0012-0.0742 -> 0.1898 | D4: =C4-B4 -> -0.0022
A5: 225 | B5: 0.198 | C5: =A5*0.0012-0.0742 -> 0.1958 | D5: =C5-B5 -> -0.0022
A6: 230 | B6: 0.203 | C6: =A6*0.0012-0.0742 -> 0.2018 | D6: =C6-B6 -> -0.0012
A7: 235 | B7: 0.209 | C7: =A7*0.0012-0.0742 -> 0.2078 | D7: =C7-B7 -> -0.0012
A8: 240 | B8: 0.215 | C8: =A8*0.0012-0.0742 -> 0.2138 | D8: =C8-B8 -> -0.0012
A9: 245 | B9: 0.221 | C9: =A9*0.0012-0.0742 -> 0.2198 | D9: =C9-B9 -> -0.0012
A10: 250 | B10: 0.227 | C10: =A10*0.0012-0.0742 -> 0.2258 | D10: =C10-B10 -> -0.0012
A11: 255 | B11: 0.232 | C11: =A11*0.0012-0.0742 -> 0.2318 | D11: =C11-B11 -> -0.0002
A12: 260 | B12: 0.238 | C12: =A12*0.0012-0.0742 -> 0.2378 | D12: =C12-B12 -> -0.0002
A13: 265 | B13: 0.244 | C13: =A13*0.0012-0.0742 -> 0.2438 | D13: =C13-B13 -> -0.0002
... A26: 330 | B26: 0.319 | C26: =A26*0.0012-0.0742 -> 0.3218 | D26: =C26-B26 -> 0.0028

Sheet COLUNA 30
A1: Hp/A | B1: ESP | C1: y = -1E-06x2 + 0,0011x + 0,1191
